Workbook

Sheet 단위공정별S.T(상부)
C2: # 단위 공정별 CAPA 현황(현재 CAPA)
B3: 공정 | D3: 단위공정 | E3: S/T | F3: DAY | G3: MAX인원 | H3: 현 인원 | I3: 1日 근무시간 | J3: 생산효율 | K3: 불량율 (%) | L3: 시간당 생산량 | M3: 시간당 맥스CAPA | N3: 하루 생산량 | O3: 일 MAX CAPA | P3: 월 CAPA | Q3: 월 MAX CAPA | R3: 년 CAPA | S3: 년 MAX CAPA | T3: 작업자 | U3: 비고
E4: (sec.) | F4: (日) | G4: - | H4: - | I4: 8hr 기준 (S) | J4: (%) | K4: (%) | L4: UPH | M4: (시간_1hr/EA) | N4: UPD(8/hr) | O4: (일_8hr/EA) | P4: UPM | Q4: (월/EA) | R4: UPY | S4: (년/EA) | T4: -
C5: 입고검사 | D5: 외경파이 치수 검사(등급별) | E5: 4.4 | F5: 20 | H5: 1 | I5: =60*60*8 -> 28800 | J5: 0.8 | K5: 0 | L5: =(3600/E5)*H5*J5*(1-K5) -> 654.54545 | N5: =L5*8 -> 5236.3636 | P5: =(N5+#REF!)*F5 -> #REF! | R5: =P5*12 -> #REF!
B6: 검사 | C6: 수입검사 | D6: 제품별 수입검사 진행 | F6: 20 | H6: 1 | J6: 0.95 | K6: 0 | L6: =IFERROR((3600/E6)*H6*J6*(1-K6),) -> 0 | M6: =(3600/E6)*G6*J6*(1-K6) -> #DIV/0! | N6: =L6*8 -> 0 | O6: =M6*23 -> #DIV/0! | P6: =(N6)*F6 -> 0 | Q6: =O6*F6 -> #DIV/0! | R6: =P6*12 -> 0 | U6: 입고수량의 10% 수입검사 / 협의해서 수량 해야함
B7: 후공정 | C7: 샌딩 | D7: 상부제품 샌딩 진행 | E7: 45 | F7: 20 | H7: 1 | J7: 0.95 | K7: 0 | L7: =(3600/E7)*H7*J7*(1-K7) -> 76 | M7: =(3600/E7)*G7*J7*(1-K7) -> 0 | N7: =L7*8 -> 608 | O7: =M7*23 -> 0 | P7: =(N7)*F7 -> 12160 | Q7: =O7*F7 -> 0 | R7: =P7*12 -> 145920 | U7: C/T 측정 다시 해봐야함
B8: 세척 | C8: 최종 세척 | D8: 검사 완료 후 최종 세척 | E8: 6 | F8: 20 | H8: 1 | J8: 0.95 | K8: 0 | L8: =(3600/E8)*H8*J8*(1-K8) -> 570 | M8: =(3600/E8)*G8*J8*(1-K8) -> 0 | N8: =L8*8 -> 4560 | O8: =M8*23 -> 0 | P8: =(N8)*F8 -> 91200 | Q8: =O8*F8 -> 0 | R8: =P8*12 -> 1094400
B9: 상부외 포장 | C9: 포장 | D9: 제품 설명서 투입 및 실링 후 | E9: 9.2 | F9: 20 | G9: 1 | H9: 1 | I9: =60*60*8 -> 28800 | J9: 0.95 | K9: 0 | L9: =(3600/E9)*H9*J9*(1-K9) -> 371.73913 | M9: =(3600/E9)*G9*J9*(1-K9) -> 371.73913 | N9: =L9*8 -> 2973.913 | O9: =M9*23 -> 8550 | P9: =(N9)*F9 -> 59478.261 | Q9: =O9*F9 -> 171000 | R9: =P9*12 -> 713739.13 | S9: =Q9*12 -> 2052000
C10: 완제품 포장 | D10: 제품 실링 및 라벨부착 완포장 | E10: 27.2 | F10: 20 | G10: 0.5 | H10: 2 | J10: 0.95 | K10: 0 | L10: =(3600/E10)*H10*J10*(1-K10) -> 251.47059 | M10: =(3600/E10)*G10*J10*(1-K10) -> 62.867647 | N10: =L10*8 -> 2011.7647 | O10: =M10*23 -> 1445.9559 | P10: =(N10)*F10 -> 40235.294 | Q10: =O10*F10 -> 28919.118 | R10: =P10*12 -> 482823.53
K15: 불량율 (%) | L15: 시간당 생산량 | N15: 정규시간 CAPA | P15: 생산 CAPA | R15: 생산 CAPA
K16: (%) | L16: (EA) | N16: (일_8hr/EA) | P16: (월/EA) | R16: (년/EA)
K17: 0 | L17: =(3600/E17)*H17*J17*(1-K17) -> #DIV/0! | N17: =L17*8 -> #DIV/0! | P17: =(N17+#REF!)*F17 -> #DIV/0! | R17: =P17*12 -> #DIV/0!
K18: 0 | L18: =(3600/E18)*H18*J18*(1-K18) -> #DIV/0! | N18: =L18*8 -> #DIV/0! | P18: =(N18+#REF!)*F18 -> #DIV/0! | R18: =P18*12 -> #DIV/0!
K19: 0 | L19: =(3600/E19)*H19*J19*(1-K19) -> #DIV/0! | N19: =L19*8 -> #DIV/0! | P19: =(N19+#REF!)*F19 -> #DIV/0! | R19: =P19*12 -> #DIV/0!
K20: 0 | L20: =(3600/E20)*H20*J20*(1-K20) -> #DIV/0! | N20: =L20*8 -> #DIV/0! | P20: =(N20+#REF!)*F20 -> #DIV/0! | R20: =P20*12 -> #DIV/0!
K21: 0 | L21: =(3600/E21)*H21*J21*(1-K21) -> #DIV/0! | N21: =L21*8 -> #DIV/0! | P21: =(N21+#REF!)*F21 -> #DIV/0! | R21: =P21*12 -> #DIV/0!
K22: 0 | L22: =(3600/E22)*H22*J22*(1-K22) -> #DIV/0! | N22: =L22*8 -> #DIV/0! | P22: =(N22+#REF!)*F22 -> #DIV/0! | R22: =P22*12 -> #DIV/0!
K23: 0 | L23: =(3600/E23)*H23*J23*(1-K23) -> #DIV/0! | N23: =L23*8 -> #DIV/0! | P23: =(N23+#REF!)*F23 -> #DIV/0! | R23: =P23*12 -> #DIV/0!

Sheet 단위공정별S.T(Fixture)
C2: # 단위 공정별 CAPA 현황(현재 CAPA)
B3: 공정 | D3: 단위공정 | E3: S/T | F3: DAY | G3: MAX인원 | H3: 현 인원 | I3: 1日 근무시간 | J3: 생산효율 | K3: 불량율 (%) | L3: 시간당 생산량 | M3: 시간당 맥스CAPA | N3: 하루 생산량 | O3: 일 MAX CAPA | P3: 월 CAPA | Q3: 월 MAX CAPA | R3: 년 CAPA | S3: 년 MAX CAPA | T3: 작업자 | U3: 비고
E4: (sec.) | F4: (日) | G4: - | H4: - | I4: 8hr 기준 (S) | J4: (%) | K4: (%) | L4: UPH | M4: (시간_1hr/EA) | N4: UPD(8/hr) | O4: (일_8hr/EA) | P4: UPM | Q4: (월/EA) | R4: UPY | S4: (년/EA) | T4: -
C5: 입고검사 | D5: 외경파이 치수 검사(등급별) | E5: 4.4 | F5: 20 | H5: 1 | I5: =60*60*8 -> 28800 | J5: 0.8 | K5: 0 | L5: =(3600/E5)*H5*J5*(1-K5) -> 654.54545 | N5: =L5*8 -> 5236.3636 | P5: =(N5+#REF!)*F5 -> #REF! | R5: =P5*12 -> #REF!
B6: 가공 공정 | C6: CNC 가공 | D6: CNC 1호기 | E6: 192.5 | F6: 30 | G6: 1 | H6: 1 | I6: =60*60*8 -> 28800 | J6: 0.9 | K6: 0.01 | L6: =(3600/E6)*H6*J6*(1-K6) -> 16.662857 | M6: =(3600/E6)*G6*J6*(1-K6) -> 16.662857 | N6: =L6*24 -> 399.90857 | O6: =M6*23 -> 383.24571 | P6: =(N6)*F6 -> 11997.257 | Q6: =O6*F6 -> 11497.371 | R6: =P6*12 -> 143967.09 | S6: =Q6*12 -> 137968.46 | T6: 오석범 | U6: 픽처.레굴러.와이드
D7: CNC 2호기 | E7: 256.5 | F7: 30 | G7: 1 | H7: 1 | I7: =60*60*8 -> 28800 | J7: 0.9 | K7: 0.01 | L7: =(3600/E7)*H7*J7*(1-K7) -> 12.505263 | M7: =(3600/E7)*G7*J7*(1-K7) -> 12.505263 | N7: =L7*24 -> 300.12632 | O7: =M7*23 -> 287.62105 | P7: =(N7)*F7 -> 9003.7895 | Q7: =O7*F7 -> 8628.6316 | R7: =P7*12 -> 108045.47 | S7: =Q7*12 -> 103543.58 | T7: 오석범 | U7: 픽처 미니
D8: CNC 3호기 | E8: 192.5 | F8: 30 | G8: 1 | H8: 1 | I8: =60*60*8 -> 28800 | J8: 0.9 | K8: 0.01 | L8: =(3600/E8)*H8*J8*(1-K8) -> 16.662857 | M8: =(3600/E8)*G8*J8*(1-K8) -> 16.662857 | N8: =L8*24 -> 399.90857 | O8: =M8*23 -> 383.24571 | P8: =(N8)*F8 -> 11997.257 | Q8: =O8*F8 -> 11497.371 | R8: =P8*12 -> 143967.09 | S8: =Q8*12 -> 137968.46 | T8: 오석범 | U8: 픽처.레굴러.와이드
D9: CNC 4호기 | E9: 192.5 | F9: 30 | G9: 1 | H9: 1 | I9: =60*60*8 -> 28800 | J9: 0.9 | K9: 0.01 | L9: =(3600/E9)*H9*J9*(1-K9) -> 16.662857 | M9: =(3600/E9)*G9*J9*(1-K9) -> 16.662857 | N9: =L9*24 -> 399.90857 | O9: =M9*23 -> 383.24571 | P9: =(N9)*F9 -> 11997.257 | Q9: =O9*F9 -> 11497.371 | R9: =P9*12 -> 143967.09 | S9: =Q9*12 -> 137968.46 | T9: 오석범 | U9: 픽처.레굴러.와이드
E10: 240 | F10: 20 | G10: 1 | I10: =60*60*8 -> 28800 | J10: 0.9 | K10: 0.02 | L10: =(3600/E10)*H10*J10*(1-K10) -> 0 | M10: =(3600/E10)*G10*J10*(1-K10) -> 13.23 | N10: =L10*24 -> 0 | O10: =M10*23 -> 304.29 | P10: =(N10)*F10 -> 0 | Q10: =O10*F10 -> 6085.8 | R10: =P10*12 -> 0 | S10: =Q10*12 -> 73029.6 | T10: 오석범
E11: 480 | F11: 20 | G11: 1 | I11: =60*60*8 -> 28800 | J11: 0.9 | K11: 0.02 | L11: =(3600/E11)*H11*J11*(1-K11) -> 0 | M11: =(3600/E11)*G11*J11*(1-K11) -> 6.615 | N11: =L11*24 -> 0 | O11: =M11*23 -> 152.145 | P11: =(N11)*F11 -> 0 | Q11: =O11*F11 -> 3042.9 | R11: =P11*12 -> 0 | S11: =Q11*12 -> 36514.8 | T11: 오석범
E12: 75 | F12: 20 | G12: 1 | I12: =60*60*8 -> 28800 | J12: 0.9 | K12: 0.02 | L12: =(3600/E12)*H12*J12*(1-K12) -> 0 | M12: =(3600/E12)*G12*J12*(1-K12) -> 42.336 | N12: =L12*24 -> 0 | O12: =M12*23 -> 973.728 | P12: =(N12)*F12 -> 0 | Q12: =O12*F12 -> 19474.56 | R12: =P12*12 -> 0 | S12: =Q12*12 -> 233694.72 | T12: 오석범
D13: 초품 검사(LOT/1EA) | E13: 4 | F13: 20 | G13: 1 | I13: =60*60*8 -> 28800 | J13: 0.9 | K13: 0 | L13: =(3600/E13)*H13*J13*(1-K13) -> 0 | M13: =(3600/E13)*G13*J13*(1-K13) -> 810 | N13: =L13*8 -> 0 | O13: =M13*23 -> 18630 | P13: =(N13)*F13 -> 0 | Q13: =O13*F13 -> 372600 | R13: =P13*12 -> 0 | S13: =Q13*12 -> 4471200 | T13: 오석범
D14: Air세정 | E14: 10 | F14: 20 | G14: 1 | I14: =60*60*8 -> 28800 | J14: 0.9 | K14: 0 | L14: =(3600/E14)*H14*J14*(1-K14) -> 0 | M14: =(3600/E14)*G14*J14*(1-K14) -> 324 | N14: =L14*8 -> 0 | O14: =M14*23 -> 7452 | P14: =(N14)*F14 -> 0 | Q14: =O14*F14 -> 149040 | R14: =P14*12 -> 0 | S14: =Q14*12 -> 1788480 | T14: 오석범
D15: 탈지 | E15: 9 | F15: 20 | G15: 1 | H15: 1 | I15: =60*60*8 -> 28800 | J15: 0.9 | K15: 0 | L15: =(3600/E15)*H15*J15*(1-K15) -> 360 | M15: =(3600/E15)*G15*J15*(1-K15) -> 360 | N15: =L15*8 -> 2880 | O15: =M15*23 -> 8280 | P15: =(N15)*F15 -> 57600 | Q15: =O15*F15 -> 165600 | R15: =P15*12 -> 691200 | S15: =Q15*12 -> 1987200 | T15: 오석범 | U15: CNC 인원이 탈지~세척 자동라인이라 1명으로 문제없음
B16: 후공정 | C16: 1차 외관검사 | D16: 전장 길이.체결검사.외관:전수검사 | E16: 27 | F16: 20 | G16: 3 | H16: 3 | I16: =60*60*8 -> 28800 | J16: 0.9 | K16: 0.01 | L16: =(3600/E16)*H16*J16*(1-K16) -> 356.4 | M16: =(3600/E16)*G16*J16*(1-K16) -> 356.4 | N16: =L16*8 -> 2851.2 | O16: =M16*23 -> 8197.2 | P16: =(N16)*F16 -> 57024 | Q16: =O16*F16 -> 163944 | R16: =P16*12 -> 684288 | S16: =Q16*12 -> 1967328 | T16: QC
C17: 1차수동 세척 | D17: 수동 세척 | E17: 4.5 | F17: 20 | G17: 1 | H17: 1 | I17: =60*60*8 -> 28800 | J17: 0.9 | K17: 0 | L17: =(3600/E17)*H17*J17*(1-K17) -> 720 | M17: =(3600/E17)*G17*J17*(1-K17) -> 720 | N17: =L17*8 -> 5760 | O17: =M17*23 -> 16560 | P17: =(N17)*F17 -> 115200 | Q17: =O17*F17 -> 331200 | R17: =P17*12 -> 1382400 | S17: =Q17*12 -> 3974400 | T17: 사무실 대응
C18: 샌딩 | D18: 픽스처 핀지그, 와셔 픽스처 조립 | E18: 12.9 | F18: 20 | G18: 1 | H18: 1 | I18: =60*60*8 -> 28800 | J18: 0.9 | K18: 0 | L18: =(3600/E18)*H18*J18*(1-K18) -> 251.16279 | M18: =(3600/E18)*G18*J18*(1-K18) -> 251.16279 | N18: =L18*8 -> 2009.3023 | P18: =(N18)*F18 -> 40186.047 | Q18: =O18*F18 -> #VALUE! | R18: =P18*12 -> 482232.56 | S18: =Q18*12 -> #VALUE! | T18: 김현식 4시간 최근호 4시간
D19: Stage:8구 | E19: 28 | F19: 20 | G19: 1.5 | H19: 1.5 | I19: =60*60*8 -> 28800 | J19: 0.9 | K19: 0.02 | L19: =(3600/E19)*H19*J19*(1-K19) -> 170.1 | M19: =(3600/E19)*G19*J19*(1-K19) -> 170.1 | N19: =L19*12 -> 2041.2 | O19: =M19*23 -> 3912.3 | P19: =(N19)*F19 -> 40824 | Q19: =O19*F19 -> 78246 | R19: =P19*12 -> 489888 | S19: =Q19*12 -> 938952 | T19: 권일양 8시간 김현식 4시간
C20: 에칭 | D20: 에칭 Jig 조립 및 세척 | E20: 12.9 | F20: 20 | G20: 1 | H20: 1 | I20: =60*60*8 -> 28800 | J20: 0.9 | K20: 0 | L20: =(3600/E20)*H20*J20*(1-K20) -> 251.16279 | M20: =(3600/E20)*G20*J20*(1-K20) -> 251.16279 | N20: =L20*8 -> 2009.3023 | O20: =M20*23 -> 5776.7442 | P20: =(N20)*F20 -> 40186.047 | Q20: =O20*F20 -> 115534.88 | R20: =P20*12 -> 482232.56 | S20: =Q20*12 -> 1386418.6 | T20: 송정화
D21: 에칭 | E21: 5.8 | F21: 20 | G21: 1 | H21: 1 | I21: =60*60*8 -> 28800 | J21: 0.9 | K21: 0.1 | L21: =(3600/E21)*H21*J21*(1-K21) -> 502.75862 | M21: =(3600/E21)*G21*J21*(1-K21) -> 502.75862 | N21: =L21*4 -> 2011.0345 | O21: =M21*23 -> 11563.448 | P21: =(N21)*F21 -> 40220.69 | Q21: =O21*F21 -> 231268.97 | R21: =P21*12 -> 482648.28 | S21: =Q21*12 -> 2775227.6 | T21: 최근호 | U21: 실제 C/T와 다르지만 2K로 케파 맞춤(이사님 지시사항)
D22: Jig 분리 | E22: 8 | F22: 20 | G22: 1 | H22: 1 | I22: =60*60*8 -> 28800 | J22: 0.9 | K22: 0 | L22: =(3600/E22)*H22*J22*(1-K22) -> 405 | M22: =(3600/E22)*G22*J22*(1-K22) -> 405 | N22: =L22*8 -> 3240 | O22: =M22*23 -> 9315 | P22: =(N22)*F22 -> 64800 | Q22: =O22*F22 -> 186300 | R22: =P22*12 -> 777600 | S22: =Q22*12 -> 2235600 | T22: 송정화
C23: PH(LOT) | D23: LOT/1회(샘플링) | E23: 1 | F23: 20 | G23: 1 | I23: =60*60*8 -> 28800 | J23: 0.9 | K23: 0 | L23: =(3600/E23)*H23*J23*(1-K23) -> 0 | M23: =(3600/E23)*G23*J23*(1-K23) -> 3240 | N23: =L23*8 -> 0 | O23: =M23*23 -> 74520 | P23: =(N23)*F23 -> 0 | Q23: =O23*F23 -> 1490400 | R23: =P23*12 -> 0 | S23: =Q23*12 -> 17884800
C24: 전도도 | E24: 1 | F24: 20 | G24: 1 | I24: =60*60*8 -> 28800 | J24: 0.9 | K24: 0 | L24: =(3600/E24)*H24*J24*(1-K24) -> 0 | M24: =(3600/E24)*G24*J24*(1-K24) -> 3240 | N24: =L24*8 -> 0 | O24: =M24*23 -> 74520 | P24: =(N24)*F24 -> 0 | Q24: =O24*F24 -> 1490400 | R24: =P24*12 -> 0 | S24: =Q24*12 -> 17884800
C25: 표면조도 | E25: 1 | F25: 20 | G25: 1 | I25: =60*60*8 -> 28800 | J25: 0.9 | K25: 0 | L25: =(3600/E25)*H25*J25*(1-K25) -> 0 | M25: =(3600/E25)*G25*J25*(1-K25) -> 3240 | N25: =L25*8 -> 0 | O25: =M25*23 -> 74520 | P25: =(N25)*F25 -> 0 | Q25: =O25*F25 -> 1490400 | R25: =P25*12 -> 0 | S25: =Q25*12 -> 17884800
C26: SEM/EDS촬영 | D26: 에칭 6LOT/1LOT/2EA | E26: 1.5 | F26: 20 | G26: 1 | I26: =60*60*8 -> 28800 | J26: 0.9 | K26: 0 | L26: =(3600/E26)*H26*J26*(1-K26) -> 0 | M26: =(3600/E26)*G26*J26*(1-K26) -> 2160 | N26: =L26*8 -> 0 | O26: =M26*23 -> 49680 | P26: =(N26)*F26 -> 0 | Q26: =O26*F26 -> 993600 | R26: =P26*12 -> 0 | S26: =Q26*12 -> 11923200
B27: 클린룸 | C27: 2차 자동 세척 | D27: 세척 | E27: 4.57 | F27: 20 | G27: 1 | H27: 1 | I27: =60*60*8 -> 28800 | J27: 0.9 | K27: 0 | L27: =(3600/E27)*H27*J27*(1-K27) -> 708.97155 | M27: =(3600/E27)*G27*J27*(1-K27) -> 708.97155 | N27: =L27*8 -> 5671.7724 | O27: =M27*23 -> 16306.346 | P27: =(N27)*F27 -> 113435.45 | Q27: =O27*F27 -> 326126.91 | R27: =P27*12 -> 1361225.4 | S27: =Q27*12 -> 3913523 | T27: 박찬실 | U27: 최초 생산 2시간40분 소요 이후 배출 16분 간격 | W27: ← 2시간 40분 최초 배출 : 300EA / 5시간20분 320분÷16분 = 20회*300EA = 총생산수량 6,300EA
C28: 2차 외관검사 | D28: 전수검사 | E28: 16 | F28: 20 | G28: 1 | H28: 1 | I28: =60*60*8 -> 28800 | J28: 0.9 | K28: 0.03 | L28: =(3600/E28)*H28*J28*(1-K28) -> 196.425 | M28: =(3600/E28)*G28*J28*(1-K28) -> 196.425 | N28: =L28*8 -> 1571.4 | O28: =M28*23 -> 4517.775 | P28: =(N28)*F28 -> 31428 | Q28: =O28*F28 -> 90355.5 | R28: =P28*12 -> 377136 | S28: =Q28*12 -> 1084266 | T28: QC | W28: ← 8시간 기준 28,800초÷6,300EA = 4.57초ST
C29: 최종 조립 | D29: 가조립(아웃캡,인바디)체결 → 앰플 스티커 출력 및 타이백 → 픽스처 조립(프레스) → 커버스크류, 실리콘캡 조립 | E29: 25 | F29: 20 | G29: 2 | H29: 1.5 | I29: =60*60*8 -> 28800 | J29: 0.9 | K29: 0 | L29: =(3600/E29)*H29*J29*(1-K29) -> 194.4 | M29: =(3600/E29)*G29*J29*(1-K29) -> 259.2 | N29: =L29*8 -> 1555.2 | O29: =M29*23 -> 5961.6 | P29: =(N29)*F29 -> 31104 | Q29: =O29*F29 -> 119232 | R29: =P29*12 -> 373248 | S29: =Q29*12 -> 1430784 | T29: 이명희 박찬실 | U29: 실제 C/T와 다르지만 2K로 케파 맞춤(이사님 지시사항)
C30: 자동 실링 포장 | D30: 자동 실링 포장 | E30: 12 | F30: 20 | G30: 1 | H30: 1 | I30: =60*60*8 -> 28800 | J30: 0.9 | K30: 0.03 | L30: =(3600/E30)*H30*J30*(1-K30) -> 261.9 | M30: =(3600/E30)*G30*J30*(1-K30) -> 261.9 | N30: =L30*8 -> 2095.2 | O30: =M30*23 -> 6023.7 | P30: =(N30)*F30 -> 41904 | Q30: =O30*F30 -> 120474 | R30: =P30*12 -> 502848 | S30: =Q30*12 -> 1445688 | T30: 박찬실
B31: 참고용 | C31: 후공정검사 | D31: PH/전도도 , 표면조도 , SEM / EDS , 최종검사 | L31: =(3600/E31)*H31*J31*(1-K31) -> #DIV/0!
B32: 외주 | C32: 멸균 | D32: 감마:3일 소요 | E32: 541 | F32: 20 | G32: 1 | H32: 0 | I32: =60*60*8 -> 28800 | J32: 0.9 | K32: 0 | L32: =(3600/E32)*H32*J32*(1-K32) -> 0 | M32: =(3600/E32)*G32*J32*(1-K32) -> 5.9889094 | N32: =L32*8 -> 0 | O32: =M32*23 -> 137.74492 | P32: =(N32)*F32 -> 0 | Q32: =O32*F32 -> 2754.8983 | R32: =P32*12 -> 0 | S32: =Q32*12 -> 33058.78 | T32: - | U32: 멸균 출고 후 입고까지 3일 소요 박스당 약 1K
B33: 픽스처 포장 | C33: 포장 전 준비작업 | D33: 단상자 준비 및 라벨스티커 부착, 스펙라벨 동봉 | E33: 4.5 | F33: 20 | G33: 1 | H33: 0.5 | I33: =60*60*8 -> 28800 | J33: 0.9 | K33: 0 | L33: =(3600/E33)*H33*J33*(1-K33) -> 360 | M33: =(3600/E33)*G33*J33*(1-K33) -> 720 | N33: =L33*8 -> 2880 | O33: =M33*23 -> 16560 | P33: =(N33)*F33 -> 57600 | Q33: =O33*F33 -> 331200 | R33: =P33*12 -> 691200 | S33: =Q33*12 -> 3974400 | T33: 이민희
C34: 제품 포장 | D34: 제품 포장 | E34: 21.5 | F34: 20 | G34: 2 | H34: 2 | J34: 0.9 | K34: 0 | L34: =(3600/E34)*H34*J34*(1-K34) -> 301.39535 | M34: =(3600/E34)*G34*J34*(1-K34) -> 301.39535 | N34: =L34*8 -> 2411.1628 | O34: =M34*23 -> 6932.093 | P34: =(N34)*F34 -> 48223.256 | Q34: =O34*F34 -> 138641.86 | R34: =P34*12 -> 578679.07 | T34: 윤장미,이민희,최유라 | U34: 실제 C/T와 다르지만 2K로 케파 맞춤(이사님 지시사항)
C35: 완제품 포장 | D35: 완제품 단프라 박스 포장 | E35: 6 | F35: 20 | G35: 0.5 | H35: 0.5 | J35: 0.9 | K35: 0 | L35: =(3600/E35)*H35*J35*(1-K35) -> 270 | M35: =(3600/E35)*G35*J35*(1-K35) -> 270 | N35: =L35*8 -> 2160 | O35: =M35*23 -> 6210 | P35: =(N35)*F35 -> 43200 | Q35: =O35*F35 -> 124200 | R35: =P35*12 -> 518400 | T35: 사무실대응
C36: 포장검사(출하) | D36: LOT/2EA(샘플링)/외관.라벨 | E36: 16 | F36: 20 | G36: 2 | H36: 2 | I36: =60*60*8 -> 28800 | J36: 0.9 | K36: 0 | L36: =(3600/E36)*H36*J36*(1-K36) -> 405 | M36: =(3600/E36)*G36*J36*(1-K36) -> 405 | N36: =L36*8 -> 3240 | O36: =M36*23 -> 9315 | P36: =(N36)*F36 -> 64800 | Q36: =O36*F36 -> 186300 | R36: =P36*12 -> 777600 | S36: =Q36*12 -> 2235600 | T36: QA
K41: 불량율 (%) | L41: 시간당 생산량 | N41: 정규시간 CAPA | P41: 생산 CAPA | R41: 생산 CAPA
K42: (%) | L42: (EA) | N42: (일_8hr/EA) | P42: (월/EA) | R42: (년/EA)
K43: 0 | L43: =(3600/E43)*H43*J43*(1-K43) -> #DIV/0! | N43: =L43*8 -> #DIV/0! | P43: =(N43+#REF!)*F43 -> #DIV/0! | R43: =P43*12 -> #DIV/0!
K44: 0 | L44: =(3600/E44)*H44*J44*(1-K44) -> #DIV/0! | N44: =L44*8 -> #DIV/0! | P44: =(N44+#REF!)*F44 -> #DIV/0! | R44: =P44*12 -> #DIV/0!
K45: 0 | L45: =(3600/E45)*H45*J45*(1-K45) -> #DIV/0! | N45: =L45*8 -> #DIV/0! | P45: =(N45+#REF!)*F45 -> #DIV/0! | R45: =P45*12 -> #DIV/0!
...

Sheet Fixture 총 발주수량
B1: 해외 주문 수량
K2: 46072
A3: 품목_SUMIF | B3: CODE | C3: 2순위 CE 아자르바이젠 PO03 | D3: 신규 베트남 PO03 | E3: CE 이라크 PO30 | F3: CE 리투아니아 PO04 | G3: CE 이라크 PO31 | H3: CE 두바이 PO08 | I3: CE 몰도바PO07 | J3: 주문 합계 _ CE | K3: FDA 이란 PO26-03 | L3: 주문 합계 _ FDA | M3: 포장 재고(CE) | N3: 포장재고(FDA) | O3: 출하 가능_CE | P3: 출하 가능_FDA | Q3: 멸균완료 포장대기 | R3: 출하 가능 | S3: 멸균중 | T3: 출하 가능 | U3: 멸균대기 | V3: 출하 가능 | W3: 클린룸 | X3: 출하 가능 | Y3: 2차 검사 | Z3: 출하 가능 | AA3: 샌딩 & 에칭 | AB3: 출하 가능 | AC3: 샌딩대기 재고 확인용 | AD3: 1차 검사 | AE3: 출하 가능 | AF3: CNC 가공 | AG3: 출하 가능 | AH3: 출하가능 | AJ3: 무게(g) | AK3: 양수전환 | AL3: LOT 수량 | AM3: PH 전도도 뺴야할 수량 | AN3: LOT별 빼야할 수량(4g) | AO3: ★ PH 전도도 측정 수량 뺴야함 (모델별로 4g)
A4: C1M3008 | B4: C1M3008C | D4: 0 | E4: 0 | H4: 0 | J4: 165 | K4: 500 | L4: 500 | M4: 0 | N4: 131 | O4: -165 | P4: -369 | Q4: 0 | R4: -534 | S4: 0 | T4: -534 | U4: 0 | V4: -534 | W4: 0 | X4: -534 | Y4: 0 | Z4: -534 | AA4: 0 | AB4: -534 | AC4: 0 | AD4: 0 | AE4: -534 | AF4: 0 | AG4: -534 | AH4: -596 | AJ4: 0.13 | AK4: -1.78 | AL4: 2 | AM4: 62 | AN4: 31
A5: C1M3010 | B5: C1M3010C | D5: 80 | E5: 1375 | H5: 0 | J5: 1895 | K5: 1000 | L5: 1000 | M5: 143 | N5: 96 | O5: -1752 | P5: -904 | Q5: 0 | R5: -2656 | S5: 0 | T5: -2656 | U5: 0 | V5: -2656 | W5: 0 | X5: -2656 | Y5: 618 | Z5: -2038 | AA5: 1809 | AB5: -229 | AC5: 0 | AD5: 0 | AE5: -229 | AF5: 0 | AG5: -229 | AH5: -253 | AJ5: 0.171 | AK5: -0.76333333 | AL5: 1 | AM5: 24 | AN5: 24
A6: C1M3011 | B6: C1M3011C | C6: 11 | D6: 100 | E6: 0 | H6: 0 | J6: 331 | K6: 1000 | L6: 1000 | M6: 0 | N6: 192 | O6: -331 | P6: -808 | Q6: 296 | R6: -843 | S6: 0 | T6: -843 | U6: 0 | V6: -843 | W6: 0 | X6: -843 | Y6: 0 | Z6: -843 | AA6: 0 | AB6: -843 | AC6: 0 | AD6: 0 | AE6: -843 | AF6: 0 | AG6: -843 | AH6: -903 | AJ6: 0.21 | AK6: -2.81 | AL6: 3 | AM6: 60 | AN6: 20
A7: C1M3013 | B7: C1M3013C | D7: 50 | E7: 0 | H7: 0 | J7: 160 | K7: 500 | L7: 500 | M7: 59 | N7: 150 | O7: -101 | P7: -350 | Q7: 0 | R7: -451 | S7: 0 | T7: -451 | U7: 0 | V7: -451 | W7: 0 | X7: -451 | Y7: 0 | Z7: -451 | AA7: 0 | AB7: -451 | AC7: 0 | AD7: 0 | AE7: -451 | AF7: 0 | AG7: -451 | AH7: -485 | AJ7: 0.245 | AK7: -1.5033333 | AL7: 2 | AM7: 34 | AN7: 17
A8: C1M3508 | B8: C1M3508C | D8: 0 | E8: 825 | H8: 0 | J8: 1469 | K8: 1000 | L8: 1000 | M8: 403 | N8: 125 | O8: -1066 | P8: -875 | Q8: 0 | R8: -1941 | S8: 0 | T8: -1941 | U8: 0 | V8: -1941 | W8: 0 | X8: -1941 | Y8: 0 | Z8: -1941 | AA8: 665 | AB8: -1276 | AC8: 0 | AD8: 0 | AE8: -1276 | AF8: 0 | AG8: -1276 | AH8: -1401 | AJ8: 0.162 | AK8: -4.2533333 | AL8: 5 | AM8: 125 | AN8: 25
A9: C1M3510 | B9: C1M3510C | D9: 100 | E9: 0 | H9: 0 | J9: 1365 | K9: 3000 | L9: 3000 | M9: 113 | N9: 305 | O9: -1252 | P9: -2695 | Q9: 568 | R9: -3379 | S9: 0 | T9: -3379 | U9: 0 | V9: -3379 | W9: 276 | X9: -3103 | Y9: 320 | Z9: -2783 | AA9: 0 | AB9: -2783 | AC9: 1633 | AD9: 0 | AE9: -1150 | AF9: 0 | AG9: -1150 | AH9: -1230 | AJ9: 0.2 | AK9: -3.8333333 | AL9: 4 | AM9: 80 | AN9: 20
A10: C1M3511 | B10: C1M3511C | D10: 80 | E10: 0 | H10: 0 | J10: 630 | K10: 2000 | L10: 2000 | M10: 178 | N10: 47 | O10: -452 | P10: -1953 | Q10: 0 | R10: -2405 | S10: 0 | T10: -2405 | U10: 0 | V10: -2405 | W10: 0 | X10: -2405 | Y10: 0 | Z10: -2405 | AA10: 0 | AB10: -2405 | AC10: 0 | AD10: 0 | AE10: -2405 | AF10: 0 | AG10: -2405 | AH10: -2549 | AJ10: 0.25 | AK10: -8.0166667 | AL10: 9 | AM10: 144 | AN10: 16
A11: C1M3513 | B11: C1M3513C | D11: 50 | E11: 0 | H11: 0 | J11: 270 | K11: 500 | L11: 500 | M11: 0 | N11: 190 | O11: -270 | P11: -310 | Q11: 0 | R11: -580 | S11: 0 | T11: -580 | U11: 0 | V11: -580 | W11: 0 | X11: -580 | Y11: 0 | Z11: -580 | AA11: 0 | AB11: -580 | AC11: 283 | AD11: 348 | AE11: 51 | AF11: 0 | AG11: 51 | AH11: 51 | AJ11: 0.3 | AK11: 0.17 | AL11: 0 | AM11: 0 | AN11: 14
A12: C1M3508S | B12: C1M3508SC | D12: 0 | E12: 0 | H12: 0 | J12: 0 | K12: 2000 | L12: 2000 | M12: 3 | N12: 62 | O12: 3 | P12: -1938 | Q12: 0 | R12: -1938 | S12: 0 | T12: -1938 | U12: 0 | V12: -1938 | W12: 192 | X12: -1746 | Y12: 721 | Z12: -1025 | AA12: 0 | AB12: -1025 | AC12: 1605 | AD12: 0 | AE12: 580 | AF12: 0 | AG12: 580 | AH12: 580 | AJ12: 0.162 | AK12: 1.9333333 | AL12: 0 | AM12: 0 | AN12: 25
A13: C1M3510S | B13: C1M3510SC | D13: 0 | E13: 0 | H13: 0 | J13: 0 | K13: 3000 | L13: 3000 | M13: 124 | N13: 630 | O13: 124 | P13: -2370 | Q13: 524 | R13: -1846 | S13: 0 | T13: -1846 | U13: 0 | V13: -1846 | W13: 0 | X13: -1846 | Y13: 0 | Z13: -1846 | AA13: 0 | AB13: -1846 | AC13: 2446 | AD13: 0 | AE13: 600 | AF13: 0 | AG13: 600 | AH13: 600 | AJ13: 0.2 | AK13: 2 | AL13: 0 | AM13: 0 | AN13: 20
A14: C1M3511S | B14: C1M3511SC | D14: 0 | E14: 0 | H14: 0 | J14: 0 | K14: 2000 | L14: 2000 | M14: 0 | N14: 221 | O14: 0 | P14: -1779 | Q14: 194 | R14: -1585 | S14: 0 | T14: -1585 | U14: 0 | V14: -1585 | W14: 0 | X14: -1585 | Y14: 0 | Z14: -1585 | AA14: 521 | AB14: -1064 | AC14: 1222 | AD14: 0 | AE14: 158 | AF14: 0 | AG14: 158 | AH14: 158 | AJ14: 0.25 | AK14: 0.52666667 | AL14: 0 | AM14: 0 | AN14: 16
A15: C1M3513S | B15: C1M3513SC | D15: 0 | E15: 0 | H15: 0 | J15: 0 | K15: 500 | L15: 500 | M15: 3 | N15: 503 | O15: 3 | P15: 3 | Q15: 0 | R15: 0 | S15: 0 | T15: 0 | U15: 0 | V15: 0 | W15: 298 | X15: 298 | Y15: 0 | Z15: 298 | AA15: 0 | AB15: 298 | AC15: 0 | AD15: 0 | AE15: 298 | AF15: 0 | AG15: 298 | AH15: 298 | AJ15: 0.3 | AK15: 0.99333333 | AL15: 0 | AM15: 0 | AN15: 14
A16: C1R4007 | B16: C1R4007C | D16: 100 | E16: 0 | H16: 0 | J16: 430 | K16: 2000 | L16: 2000 | M16: 509 | N16: 714 | O16: 79 | P16: -1286 | Q16: 0 | R16: -1286 | S16: 0 | T16: -1286 | U16: 0 | V16: -1286 | W16: 0 | X16: -1286 | Y16: 0 | Z16: -1286 | AA16: 0 | AB16: -1286 | AC16: 0 | AD16: 0 | AE16: -1286 | AF16: 0 | AG16: -1286 | AH16: -1386 | AJ16: 0.165 | AK16: -3.215 | AL16: 4 | AM16: 100 | AN16: 25
A17: C1R4008 | B17: C1R4008C | D17: 290 | E17: 825 | H17: 200 | I17: 125 | J17: 2100 | K17: 5000 | L17: 5000 | M17: 378 | N17: 1515 | O17: -1722 | P17: -3485 | Q17: 1524 | R17: -3683 | S17: 0 | T17: -3683 | U17: 0 | V17: -3683 | W17: 0 | X17: -3683 | Y17: 0 | Z17: -3683 | AA17: 0 | AB17: -3683 | AC17: 0 | AD17: 0 | AE17: -3683 | AF17: 0 | AG17: -3683 | AH17: -3873 | AJ17: 0.22 | AK17: -9.2075 | AL17: 10 | AM17: 190 | AN17: 19
A18: C1R4010 | B18: C1R4010C | D18: 400 | E18: 1752 | H18: 500 | I18: 125 | J18: 4594 | K18: 20000 | L18: 20000 | M18: 1268 | N18: 685 | O18: -3326 | P18: -19315 | Q18: 1503 | R18: -21138 | S18: 1972 | T18: -19166 | U18: 1282 | V18: -17884 | W18: 3186 | X18: -14698 | Y18: 867 | Z18: -13831 | AA18: 472 | AB18: -13359 | AC18: 2652 | AD18: 926 | AE18: -9781 | AF18: 0 | AG18: -9781 | AH18: -10131 | AJ18: 0.292 | AK18: -24.4525 | AL18: 25 | AM18: 350 | AN18: 14
A19: C1R4011 | B19: C1R4011C | D19: 290 | E19: 1100 | H19: 0 | I19: 30 | J19: 2080 | K19: 10000 | L19: 10000 | M19: 308 | N19: 34 | O19: -1772 | P19: -9966 | Q19: 1002 | R19: -10736 | S19: 0 | T19: -10736 | U19: 432 | V19: -10304 | W19: 0 | X19: -10304 | Y19: 0 | Z19: -10304 | AA19: 0 | AB19: -10304 | AC19: 2525 | AD19: 1633 | AE19: -6146 | AF19: 0 | AG19: -6146 | AH19: -6338 | AJ19: 0.354 | AK19: -15.365 | AL19: 16 | AM19: 192 | AN19: 12
A20: C1R4013 | B20: C1R4013C | D20: 150 | E20: 0 | H20: 0 | J20: 315 | K20: 2000 | L20: 2000 | M20: 334 | N20: 560 | O20: 19 | P20: -1440 | Q20: 0 | R20: -1440 | S20: 0 | T20: -1440 | U20: 0 | V20: -1440 | W20: 0 | X20: -1440 | Y20: 0 | Z20: -1440 | AA20: 0 | AB20: -1440 | AC20: 0 | AD20: 0 | AE20: -1440 | AF20: 0 | AG20: -1440 | AH20: -1480 | AJ20: 0.4 | AK20: -3.6 | AL20: 4 | AM20: 40 | AN20: 10
A21: C1R4007S | B21: C1R4007SC | D21: 0 | E21: 0 | H21: 0 | J21: 0 | K21: 3000 | L21: 3000 | M21: 0 | N21: 63 | O21: 0 | P21: -2937 | Q21: 0 | R21: -2937 | S21: 0 | T21: -2937 | U21: 0 | V21: -2937 | W21: 0 | X21: -2937 | Y21: 0 | Z21: -2937 | AA21: 0 | AB21: -2937 | AC21: 0 | AD21: 0 | AE21: -2937 | AF21: 0 | AG21: -2937 | AH21: -3137 | AJ21: 0.165 | AK21: -7.3425 | AL21: 8 | AM21: 200 | AN21: 25
A22: C1R4008S | B22: C1R4008SC | D22: 0 | E22: 0 | H22: 0 | J22: 0 | K22: 5000 | L22: 5000 | M22: 163 | N22: 749 | O22: 163 | P22: -4251 | Q22: 0 | R22: -4251 | S22: 0 | T22: -4251 | U22: 0 | V22: -4251 | W22: 0 | X22: -4251 | Y22: 0 | Z22: -4251 | AA22: 0 | AB22: -4251 | AC22: 3734 | AD22: 737 | AE22: 220 | AF22: 0 | AG22: 220 | AH22: 220 | AJ22: 0.22 | AK22: 0.55 | AL22: 0 | AM22: 0 | AN22: 19
A23: C1R4010S | B23: C1R4010SC | D23: 0 | E23: 0 | H23: 0 | J23: 0 | K23: 20000 | L23: 20000 | M23: 251 | N23: 8651 | O23: 251 | P23: -11349 | Q23: 2508 | R23: -8841 | S23: 2429 | T23: -6412 | U23: 1289 | V23: -5123 | W23: 634 | X23: -4489 | Y23: 2149 | Z23: -2340 | AA23: 1187 | AB23: -1153 | AC23: 2188 | AD23: 0 | AE23: 1035 | AF23: 0 | AG23: 1035 | AH23: 1035 | AJ23: 0.292 | AK23: 2.5875 | AL23: 0 | AM23: 0 | AN23: 14
A24: C1R4011S | B24: C1R4011SC | D24: 0 | E24: 0 | H24: 0 | J24: 0 | K24: 10000 | L24: 10000 | M24: 97 | N24: 656 | O24: 97 | P24: -9344 | Q24: 261 | R24: -9083 | S24: 0 | T24: -9083 | U24: 0 | V24: -9083 | W24: 617 | X24: -8466 | Y24: 645 | Z24: -7821 | AA24: 518 | AB24: -7303 | AC24: 7895 | AD24: 0 | AE24: 592 | AF24: 0 | AG24: 592 | AH24: 592 | AJ24: 0.354 | AK24: 1.48 | AL24: 0 | AM24: 0 | AN24: 12
A25: C1R4013S | B25: C1R4013SC | D25: 0 | E25: 0 | H25: 0 | J25: 0 | K25: 3000 | L25: 3000 | M25: 429 | N25: 496 | O25: 429 | P25: -2504 | Q25: 0 | R25: -2504 | S25: 0 | T25: -2504 | U25: 0 | V25: -2504 | W25: 346 | X25: -2158 | Y25: 0 | Z25: -2158 | AA25: 0 | AB25: -2158 | AC25: 2567 | AD25: 0 | AE25: 409 | AF25: 0 | AG25: 409 | AH25: 409 | AJ25: 0.4 | AK25: 1.0225 | AL25: 0 | AM25: 0 | AN25: 10
A26: C1R4507 | B26: C1R4507C | D26: 50 | E26: 0 | H26: 0 | J26: 215 | K26: 3000 | L26: 3000 | M26: 110 | N26: 3371 | O26: -105 | P26: 371 | Q26: 0 | R26: -105 | S26: 0 | T26: -105 | U26: 0 | V26: -105 | W26: 0 | X26: -105 | Y26: 0 | Z26: -105 | AA26: 0 | AB26: -105 | AC26: 0 | AD26: 0 | AE26: -105 | AF26: 0 | AG26: -105 | AH26: -125 | AJ26: 0.2 | AK26: -0.2625 | AL26: 1 | AM26: 20 | AN26: 20
A27: C1R4508 | B27: C1R4508C | D27: 300 | E27: 0 | H27: 80 | J27: 930 | K27: 3000 | L27: 3000 | M27: 237 | N27: 447 | O27: -693 | P27: -2553 | Q27: 0 | R27: -3246 | S27: 0 | T27: -3246 | U27: 0 | V27: -3246 | W27: 0 | X27: -3246 | Y27: 0 | Z27: -3246 | AA27: 0 | AB27: -3246 | AC27: 0 | AD27: 0 | AE27: -3246 | AF27: 0 | AG27: -3246 | AH27: -3390 | AJ27: 0.26 | AK27: -8.115 | AL27: 9 | AM27: 144 | AN27: 16
A28: C1R4510 | B28: C1R4510C | C28: 64 | D28: 400 | E28: 0 | F28: 6 | H28: 180 | J28: 1475 | K28: 14000 | L28: 14000 | M28: 0 | N28: 55 | O28: -1475 | P28: -13945 | Q28: 1499 | R28: -13921 | S28: 0 | T28: -13921 | U28: 0 | V28: -13921 | W28: 420 | X28: -13501 | Y28: 1670 | Z28: -11831 | AA28: 806 | AB28: -11025 | AC28: 2694 | AD28: 337 | AE28: -7994 | AF28: 0 | AG28: -7994 | AH28: -8234 | AJ28: 0.34 | AK28: -19.985 | AL28: 20 | AM28: 240 | AN28: 12
A29: C1R4511 | B29: C1R4511C | D29: 200 | E29: 0 | H29: 0 | J29: 420 | K29: 5000 | L29: 5000 | M29: 324 | N29: 57 | O29: -96 | P29: -4943 | Q29: 0 | R29: -5039 | S29: 0 | T29: -5039 | U29: 0 | V29: -5039 | W29: 0 | X29: -5039 | Y29: 0 | Z29: -5039 | AA29: 0 | AB29: -5039 | AC29: 0 | AD29: 0 | AE29: -5039 | AF29: 0 | AG29: -5039 | AH29: -5169 | AJ29: 0.4 | AK29: -12.5975 | AL29: 13 | AM29: 130 | AN29: 10
A30: C1R4513 | B30: C1R4513C | D30: 60 | E30: 0 | H30: 0 | J30: 225 | K30: 2000 | L30: 2000 | M30: 106 | N30: 1402 | O30: -119 | P30: -598 | Q30: 0 | R30: -717 | S30: 0 | T30: -717 | U30: 0 | V30: -717 | W30: 0 | X30: -717 | Y30: 0 | Z30: -717 | AA30: 0 | AB30: -717 | AC30: 0 | AD30: 0 | AE30: -717 | AF30: 0 | AG30: -717 | AH30: -735 | AJ30: 0.478 | AK30: -1.7925 | AL30: 2 | AM30: 18 | AN30: 9
A31: C1R5007 | B31: C1R5007C | D31: 40 | E31: 0 | H31: 0 | J31: 150 | K31: 1000 | L31: 1000 | M31: 147 | N31: 934 | O31: -3 | P31: -66 | Q31: 0 | R31: -69 | S31: 0 | T31: -69 | U31: 0 | V31: -69 | W31: 0 | X31: -69 | Y31: 0 | Z31: -69 | AA31: 0 | AB31: -69 | AC31: 0 | AD31: 0 | AE31: -69 | AF31: 0 | AG31: -69 | AH31: -84 | AJ31: 0.27 | AK31: -0.1725 | AL31: 1 | AM31: 15 | AN31: 15
A32: C1R5008 | B32: C1R5008C | D32: 120 | E32: 0 | H32: 40 | I32: 20 | J32: 1005 | K32: 2000 | L32: 2000 | M32: 160 | N32: 354 | O32: -845 | P32: -1646 | Q32: 437 | R32: -2054 | S32: 0 | T32: -2054 | U32: 0 | V32: -2054 | W32: 0 | X32: -2054 | Y32: 0 | Z32: -2054 | AA32: 0 | AB32: -2054 | AC32: 759 | AD32: 840 | AE32: -455 | AF32: 0 | AG32: -455 | AH32: -477 | AJ32: 0.365 | AK32: -1.1375 | AL32: 2 | AM32: 22 | AN32: 11
A33: C1R5010 | B33: C1R5010C | D33: 120 | E33: 0 | H33: 0 | I33: 20 | J33: 415 | K33: 3000 | L33: 3000 | M33: 151 | N33: 293 | O33: -264 | P33: -2707 | Q33: 1430 | R33: -1541 | S33: 0 | T33: -1541 | U33: 0 | V33: -1541 | W33: 456 | X33: -1085 | Y33: 0 | Z33: -1085 | AA33: 0 | AB33: -1085 | AC33: 0 | AD33: 0 | AE33: -1085 | AF33: 0 | AG33: -1085 | AH33: -1112 | AJ33: 0.45 | AK33: -2.7125 | AL33: 3 | AM33: 27 | AN33: 9
A34: C1R5011 | B34: C1R5011C | D34: 20 | E34: 0 | H34: 0 | I34: 20 | J34: 150 | K34: 1500 | L34: 1500 | M34: 131 | N34: 438 | O34: -19 | P34: -1062 | Q34: 688 | R34: -393 | S34: 0 | T34: -393 | U34: 0 | V34: -393 | W34: 0 | X34: -393 | Y34: 0 | Z34: -393 | AA34: 0 | AB34: -393 | AC34: 0 | AD34: 0 | AE34: -393 | AF34: 0 | AG34: -393 | AH34: -401 | AJ34: 0.54 | AK34: -0.9825 | AL34: 1 | AM34: 8 | AN34: 8
A35: C1R5013 | B35: C1R5013C | D35: 0 | E35: 0 | H35: 0 | I35: 20 | J35: 102 | K35: 500 | L35: 500 | M35: 40 | N35: 1280 | O35: -62 | P35: 780 | Q35: 0 | R35: -62 | S35: 0 | T35: -62 | U35: 0 | V35: -62 | W35: 0 | X35: -62 | Y35: 0 | Z35: -62 | AA35: 0 | AB35: -62 | AC35: 0 | AD35: 0 | AE35: -62 | AF35: 0 | AG35: -62 | AH35: -69 | AJ35: 0.62 | AK35: -0.155 | AL35: 1 | AM35: 7 | AN35: 7
A36: C1R5006DB0 | B36: C1R5006DB0C | D36: 0 | E36: 0 | H36: 0 | J36: 110 | K36: 300 | L36: 300 | M36: 0 | N36: 0 | O36: -110 | P36: -300 | Q36: 0 | R36: -410 | S36: 0 | T36: -410 | U36: 0 | V36: -410 | W36: 0 | X36: -410 | Y36: 0 | Z36: -410 | AA36: 0 | AB36: -410 | AC36: 0 | AD36: 0 | AE36: -410 | AF36: 0 | AG36: -410 | AH36: -430 | AJ36: 0.418 | AK36: -1.3666667 | AL36: 2 | AM36: 20 | AN36: 10 | AO36: 국내 + CE + FDA 동시사용 (한글 포장)
A37: C1R5006DB1 | B37: C1R5006DB1C | D37: 0 | E37: 0 | H37: 0 | J37: 110 | K37: 300 | L37: 300 | M37: 35 | N37: 0 | O37: -75 | P37: -300 | Q37: 0 | R37: -375 | S37: 0 | T37: -375 | U37: 0 | V37: -375 | W37: 0 | X37: -375 | Y37: 0 | Z37: -375 | AA37: 0 | AB37: -375 | AC37: 0 | AD37: 0 | AE37: -375 | AF37: 0 | AG37: -375 | AH37: -397 | AJ37: 0.38 | AK37: -1.25 | AL37: 2 | AM37: 22 | AN37: 11 | AO37: 국내 + CE + FDA 동시사용 (한글 포장)
A38: C1R5006DB2 | B38: C1R5006DB2C | D38: 0 | E38: 0 | H38: 0 | J38: 110 | K38: 300 | L38: 300 | M38: 31 | N38: 0 | O38: -79 | P38: -300 | Q38: 0 | R38: -379 | S38: 0 | T38: -379 | U38: 0 | V38: -379 | W38: 0 | X38: -379 | Y38: 0 | Z38: -379 | AA38: 0 | AB38: -379 | AC38: 0 | AD38: 0 | AE38: -379 | AF38: 0 | AG38: -379 | AH38: -403 | AJ38: 0.345 | AK38: -1.2633333 | AL38: 2 | AM38: 24 | AN38: 12 | AO38: 국내 + CE + FDA 동시사용 (한글 포장)
A39: C1WZ6007 | B39: C1WZ6007C | D39: 0 | E39: 0 | H39: 0 | J39: 110 | K39: 300 | L39: 300 | M39: 0 | N39: 468 | O39: -110 | P39: 168 | Q39: 0 | R39: -110 | S39: 0 | T39: -110 | U39: 0 | V39: -110 | W39: 0 | X39: -110 | Y39: 0 | Z39: -110 | AA39: 0 | AB39: -110 | AC39: 0 | AD39: 0 | AE39: -110 | AF39: 0 | AG39: -110 | AH39: -120 | AJ39: 0.425 | AK39: -0.36666667 | AL39: 1 | AM39: 10 | AN39: 10 | AO39: 국내 + CE + FDA 동시사용 (한글 포장)
A40: C1WZ6008 | B40: C1WZ6008C | D40: 0 | E40: 0 | H40: 0 | J40: 110 | K40: 400 | L40: 400 | M40: 0 | N40: 224 | O40: -110 | P40: -176 | Q40: 0 | R40: -286 | S40: 0 | T40: -286 | U40: 0 | V40: -286 | W40: 0 | X40: -286 | Y40: 0 | Z40: -286 | AA40: 0 | AB40: -286 | AC40: 0 | AD40: 0 | AE40: -286 | AF40: 0 | AG40: -286 | AH40: -294 | AJ40: 0.507 | AK40: -0.95333333 | AL40: 1 | AM40: 8 | AN40: 8 | AO40: 국내 + CE + FDA 동시사용 (한글 포장)
...

Sheet TEST
B2: 기준월 | C2: 46082 | D2: Up-Data | E2: 46097 | F2: 0.68611111
B3: 납품계획 | M3: =C2 -> 46082 | N3: =M3+1 -> 46083 | O3: =N3+1 -> 46084 | P3: =O3+1 -> 46085 | Q3: =P3+1 -> 46086 | R3: =Q3+1 -> 46087 | S3: =R3+1 -> 46088 | T3: =S3+1 -> 46089 | U3: =T3+1 -> 46090 | ... AQ3: =AP3+1 -> 46112
B4: 호기 | C4: CODE | D4: Name | E4: Specificaton (CE) | F4: 1번 이란 PO26-02(FDA) 부족수량 | G4: 2번 이라크 PO29(CE) 부족수량 | H4: 3번 이란 PO26-03 부족수량 | I4: P.O 총합 | J4: 계획 합계 | K4: 차이 | L4: 1호기 종료 | M4: =M3 -> 46082 | N4: =N3 -> 46083 | O4: =O3 -> 46084 | P4: =P3 -> 46085 | Q4: =Q3 -> 46086 | R4: =R3 -> 46087 | S4: =S3 -> 46088 | T4: =T3 -> 46089 | ... AQ4: =AQ3 -> 46112
B5: 2호기 | C5: C1M3008C | D5: CORE1 Fixture | E5: Ø3.0 x 8.5mm | F5: 0 | G5: 253 | H5: 369 | I5: =IF(SUMIF('Fixture 총 발주수량'!B:B,C5,'Fixture 총 발주수량'!AG:AG)<0,ABS(SUMIF('Fixture 총 발주수량'!B:B,C5,'Fixture 총 발주수량'!AG:AG)),0) -> 534 | J5: =SUM(M5:AQ5) -> 0 | K5: =J5-(F5+G5) -> -253 | L5: =IF(K5>=0,0.0001,ABS(K5)/400) -> 0.6325
B6: 2호기 | C6: C1M3010C | D6: CORE1 Fixture | E6: Ø3.0 x 10.0mm | F6: 0 | G6: 900 | H6: 905 | I6: =IF(SUMIF('Fixture 총 발주수량'!B:B,C6,'Fixture 총 발주수량'!AG:AG)<0,ABS(SUMIF('Fixture 총 발주수량'!B:B,C6,'Fixture 총 발주수량'!AG:AG)),0) -> 229 | J6: =SUM(M6:AQ6) -> 0 | K6: =J6-(F6+G6) -> -900 | L6: =IF(K6>=0,0.0001,ABS(K6)/400) -> 2.25
B7: 2호기 | C7: C1M3011C | D7: CORE1 Fixture | E7: Ø3.0 x 11.5mm | F7: 0 | G7: 477 | H7: 771 | I7: =IF(SUMIF('Fixture 총 발주수량'!B:B,C7,'Fixture 총 발주수량'!AG:AG)<0,ABS(SUMIF('Fixture 총 발주수량'!B:B,C7,'Fixture 총 발주수량'!AG:AG)),0) -> 843 | J7: =SUM(M7:AQ7) -> 0 | K7: =J7-(F7+G7) -> -477 | L7: =IF(K7>=0,0.0001,ABS(K7)/400) -> 1.1925
B8: 2호기 | C8: C1M3013C | D8: CORE1 Fixture | E8: Ø3.0 x 13.0mm | F8: 0 | G8: 0 | H8: 0 | I8: =IF(SUMIF('Fixture 총 발주수량'!B:B,C8,'Fixture 총 발주수량'!AG:AG)<0,ABS(SUMIF('Fixture 총 발주수량'!B:B,C8,'Fixture 총 발주수량'!AG:AG)),0) -> 451 | J8: =SUM(M8:AQ8) -> 0 | K8: =J8-(F8+G8) -> 0 | L8: =IF(K8>=0,0.0001,ABS(K8)/400) -> 0.0001
B9: 2호기 | C9: C1M3508SC | D9: CORE1 Fixture | E9: Ø3.5 x 8.5mm | F9: 0 | G9: 0 | H9: 421 | I9: =IF(SUMIF('Fixture 총 발주수량'!B:B,C9,'Fixture 총 발주수량'!AG:AG)<0,ABS(SUMIF('Fixture 총 발주수량'!B:B,C9,'Fixture 총 발주수량'!AG:AG)),0) -> 0 | J9: =SUM(M9:AQ9) -> 0 | K9: =J9-(F9+G9) -> 0 | L9: =IF(K9>=0,0.0001,ABS(K9)/400) -> 0.0001
B10: 2호기 | C10: C1M3510SC | D10: CORE1 Fixture | E10: Ø3.5 x 10.0mm | F10: 0 | G10: 0 | H10: 2143 | I10: =IF(SUMIF('Fixture 총 발주수량'!B:B,C10,'Fixture 총 발주수량'!AG:AG)<0,ABS(SUMIF('Fixture 총 발주수량'!B:B,C10,'Fixture 총 발주수량'!AG:AG)),0) -> 0 | J10: =SUM(M10:AQ10) -> 0 | K10: =J10-(F10+G10) -> 0 | L10: =IF(K10>=0,0.0001,ABS(K10)/400) -> 0.0001
B11: 2호기 | C11: C1M3511SC | D11: CORE1 Fixture | E11: Ø3.5 x 11.5mm | F11: 0 | G11: 0 | H11: 1578 | I11: =IF(SUMIF('Fixture 총 발주수량'!B:B,C11,'Fixture 총 발주수량'!AG:AG)<0,ABS(SUMIF('Fixture 총 발주수량'!B:B,C11,'Fixture 총 발주수량'!AG:AG)),0) -> 0 | J11: =SUM(M11:AQ11) -> 0 | K11: =J11-(F11+G11) -> 0 | L11: =IF(K11>=0,0.0001,ABS(K11)/400) -> 0.0001
B12: 2호기 | C12: C1M3513SC | D12: CORE1 Fixture | E12: Ø3.5 x 13.0mm | F12: 0 | G12: 0 | H12: 0 | I12: =IF(SUMIF('Fixture 총 발주수량'!B:B,C12,'Fixture 총 발주수량'!AG:AG)<0,ABS(SUMIF('Fixture 총 발주수량'!B:B,C12,'Fixture 총 발주수량'!AG:AG)),0) -> 0 | J12: =SUM(M12:AQ12) -> 0 | K12: =J12-(F12+G12) -> 0 | L12: =IF(K12>=0,0.0001,ABS(K12)/400) -> 0.0001
B13: 2호기 | C13: C1M3508C | D13: CORE1 Fixture | E13: Ø3.5 x 8.5mm | F13: 0 | G13: 0 | H13: 367 | I13: =IF(SUMIF('Fixture 총 발주수량'!B:B,C13,'Fixture 총 발주수량'!AG:AG)<0,ABS(SUMIF('Fixture 총 발주수량'!B:B,C13,'Fixture 총 발주수량'!AG:AG)),0) -> 1276 | J13: =SUM(M13:AQ13) -> 0 | K13: =J13-(F13+G13) -> 0 | L13: =IF(K13>=0,0.0001,ABS(K13)/400) -> 0.0001
B14: 2호기 | C14: C1M3510C | D14: CORE1 Fixture | E14: Ø3.5 x 10.0mm | F14: 0 | G14: 591 | H14: 3000 | I14: =IF(SUMIF('Fixture 총 발주수량'!B:B,C14,'Fixture 총 발주수량'!AG:AG)<0,ABS(SUMIF('Fixture 총 발주수량'!B:B,C14,'Fixture 총 발주수량'!AG:AG)),0) -> 1150 | J14: =SUM(M14:AQ14) -> 0 | K14: =J14-(F14+G14) -> -591 | L14: =IF(K14>=0,0.0001,ABS(K14)/400) -> 1.4775
B15: 2호기 | C15: C1M3511C | D15: CORE1 Fixture | E15: Ø3.5 x 11.5mm | F15: 259 | G15: 1639 | H15: 2000 | I15: =IF(SUMIF('Fixture 총 발주수량'!B:B,C15,'Fixture 총 발주수량'!AG:AG)<0,ABS(SUMIF('Fixture 총 발주수량'!B:B,C15,'Fixture 총 발주수량'!AG:AG)),0) -> 2405 | J15: =SUM(M15:AQ15) -> 0 | K15: =J15-(F15+G15) -> -1898 | L15: =IF(K15>=0,0.0001,ABS(K15)/400) -> 4.745
B16: 2호기 | C16: C1M3513C | D16: CORE1 Fixture | E16: Ø3.5 x 13.0mm | F16: 0 | G16: 1101 | H16: 208 | I16: =IF(SUMIF('Fixture 총 발주수량'!B:B,C16,'Fixture 총 발주수량'!AG:AG)<0,ABS(SUMIF('Fixture 총 발주수량'!B:B,C16,'Fixture 총 발주수량'!AG:AG)),0) -> 0 | J16: =SUM(M16:AQ16) -> 0 | K16: =J16-(F16+G16) -> -1101 | L16: =IF(K16>=0,0.0001,ABS(K16)/400) -> 2.7525
... B26: 1호기 | C26: C1R4508C | D26: CORE1 Fixture | E26: Ø4.5 x 8.5mm | F26: 0 | G26: 0 | H26: 875 | I26: =IF(SUMIF('Fixture 총 발주수량'!B:B,C26,'Fixture 총 발주수량'!AG:AG)<0,ABS(SUMIF('Fixture 총 발주수량'!B:B,C26,'Fixture 총 발주수량'!AG:AG)),0) -> 3246 | J26: =SUM(M26:AQ26) -> 0 | K26: =J26-(F26+G26) -> 0 | L26: =IF(K26>=0,0.0001,ABS(K26)/400) -> 0.0001
C27: C1R4511C | D27: CORE1 Fixture | E27: Ø4.5 x 11.5mm | F27: 0 | G27: 0 | H27: 4678 | I27: =IF(SUMIF('Fixture 총 발주수량'!B:B,C27,'Fixture 총 발주수량'!AG:AG)<0,ABS(SUMIF('Fixture 총 발주수량'!B:B,C27,'Fixture 총 발주수량'!AG:AG)),0) -> 5039 | J27: =SUM(M27:AQ27) -> 0 | K27: =J27-(F27+G27) -> 0 | L27: =IF(K27>=0,0.0001,ABS(K27)/400) -> 0.0001
C28: C1R4513C | D28: CORE1 Fixture | E28: Ø4.5 x 13.0mm | F28: 0 | G28: 0 | H28: 0 | I28: =IF(SUMIF('Fixture 총 발주수량'!B:B,C28,'Fixture 총 발주수량'!AG:AG)<0,ABS(SUMIF('Fixture 총 발주수량'!B:B,C28,'Fixture 총 발주수량'!AG:AG)),0) -> 717 | J28: =SUM(M28:AQ28) -> 0 | K28: =J28-(F28+G28) -> 0 | L28: =IF(K28>=0,0.0001,ABS(K28)/400) -> 0.0001
C29: C1R5008C | D29: CORE1 Fixture | E29: Ø5.0 x 8.5mm | F29: 0 | G29: 476 | H29: 1884 | I29: =IF(SUMIF('Fixture 총 발주수량'!B:B,C29,'Fixture 총 발주수량'!AG:AG)<0,ABS(SUMIF('Fixture 총 발주수량'!B:B,C29,'Fixture 총 발주수량'!AG:AG)),0) -> 455 | J29: =SUM(M29:AQ29) -> 0 | K29: =J29-(F29+G29) -> -476 | L29: =IF(K29>=0,0.0001,ABS(K29)/400) -> 1.19
C30: C1R5010C | D30: CORE1 Fixture | E30: Ø5.0 x 10.0mm | F30: 0 | G30: 500 | H30: 3000 | I30: =IF(SUMIF('Fixture 총 발주수량'!B:B,C30,'Fixture 총 발주수량'!AG:AG)<0,ABS(SUMIF('Fixture 총 발주수량'!B:B,C30,'Fixture 총 발주수량'!AG:AG)),0) -> 1085 | J30: =SUM(M30:AQ30) -> 0 | K30: =J30-(F30+G30) -> -500 | L30: =IF(K30>=0,0.0001,ABS(K30)/400) -> 1.25
C31: C1R5011C | D31: CORE1 Fixture | E31: Ø5.0 x 11.5mm | F31: 0 | G31: 0 | H31: 1426 | I31: =IF(SUMIF('Fixture 총 발주수량'!B:B,C31,'Fixture 총 발주수량'!AG:AG)<0,ABS(SUMIF('Fixture 총 발주수량'!B:B,C31,'Fixture 총 발주수량'!AG:AG)),0) -> 393 | J31: =SUM(M31:AQ31) -> 0 | K31: =J31-(F31+G31) -> 0 | L31: =IF(K31>=0,0.0001,ABS(K31)/400) -> 0.0001
C32: C1R5013C | D32: CORE1 Fixture | E32: Ø5.0 x 13.0mm | F32: 0 | G32: 0 | H32: 0 | I32: =IF(SUMIF('Fixture 총 발주수량'!B:B,C32,'Fixture 총 발주수량'!AG:AG)<0,ABS(SUMIF('Fixture 총 발주수량'!B:B,C32,'Fixture 총 발주수량'!AG:AG)),0) -> 62 | J32: =SUM(M32:AQ32) -> 0 | K32: =J32-(F32+G32) -> 0 | L32: =IF(K32>=0,0.0001,ABS(K32)/400) -> 0.0001
C33: C1R4010SC | D33: CORE1 Fixture | E33: Ø4.0 x 10.0mm | F33: 0 | G33: 0 | H33: 3212 | I33: =IF(SUMIF('Fixture 총 발주수량'!B:B,C33,'Fixture 총 발주수량'!AG:AG)<0,ABS(SUMIF('Fixture 총 발주수량'!B:B,C33,'Fixture 총 발주수량'!AG:AG)),0) -> 0 | J33: =SUM(M33:AQ33) -> 0 | K33: =J33-(F33+G33) -> 0 | L33: =IF(K33>=0,0.0001,ABS(K33)/400) -> 0.0001
C34: C1R4011SC | D34: CORE1 Fixture | E34: Ø4.0 x 11.5mm | F34: 0 | G34: 0 | H34: 124 | I34: =IF(SUMIF('Fixture 총 발주수량'!B:B,C34,'Fixture 총 발주수량'!AG:AG)<0,ABS(SUMIF('Fixture 총 발주수량'!B:B,C34,'Fixture 총 발주수량'!AG:AG)),0) -> 0 | J34: =SUM(M34:AQ34) -> 0 | K34: =J34-(F34+G34) -> 0 | L34: =IF(K34>=0,0.0001,ABS(K34)/400) -> 0.0001
C35: C1R4007C | D35: CORE1 Fixture | E35: Ø4.0 x 7.0mm | F35: 0 | G35: 0 | H35: 1730 | I35: =IF(SUMIF('Fixture 총 발주수량'!B:B,C35,'Fixture 총 발주수량'!AG:AG)<0,ABS(SUMIF('Fixture 총 발주수량'!B:B,C35,'Fixture 총 발주수량'!AG:AG)),0) -> 1286 | J35: =SUM(M35:AQ35) -> 0 | K35: =J35-(F35+G35) -> 0 | L35: =IF(K35>=0,0.0001,ABS(K35)/400) -> 0.0001
C36: C1R4008C | D36: CORE1 Fixture | E36: Ø4.0 x 8.5mm | F36: 0 | G36: 199 | H36: 5000 | I36: =IF(SUMIF('Fixture 총 발주수량'!B:B,C36,'Fixture 총 발주수량'!AG:AG)<0,ABS(SUMIF('Fixture 총 발주수량'!B:B,C36,'Fixture 총 발주수량'!AG:AG)),0) -> 3683 | J36: =SUM(M36:AQ36) -> 0 | K36: =J36-(F36+G36) -> -199 | L36: =IF(K36>=0,0.0001,ABS(K36)/400) -> 0.4975
C37: C1R4507C | D37: CORE1 Fixture | E37: Ø4.5 x 7.0mm | F37: 0 | G37: 0 | H37: 985 | I37: =IF(SUMIF('Fixture 총 발주수량'!B:B,C37,'Fixture 총 발주수량'!AG:AG)<0,ABS(SUMIF('Fixture 총 발주수량'!B:B,C37,'Fixture 총 발주수량'!AG:AG)),0) -> 105 | J37: =SUM(M37:AQ37) -> 0 | K37: =J37-(F37+G37) -> 0 | L37: =IF(K37>=0,0.0001,ABS(K37)/400) -> 0.0001
C38: C1R4510C | D38: CORE1 Fixture | E38: Ø4.5 x 10.0mm | F38: 1414 | G38: 1338 | H38: 14000 | I38: =IF(SUMIF('Fixture 총 발주수량'!B:B,C38,'Fixture 총 발주수량'!AG:AG)<0,ABS(SUMIF('Fixture 총 발주수량'!B:B,C38,'Fixture 총 발주수량'!AG:AG)),0) -> 7994 | J38: =SUM(M38:AQ38) -> 0 | K38: =J38-(F38+G38) -> -2752 | L38: =IF(K38>=0,0.0001,ABS(K38)/400) -> 6.88
... C45: C1R5007C | D45: CORE1 Fixture | E45: Ø5.0 x 7.0mm | F45: 0 | G45: 175 | H45: 66 | I45: =IF(SUMIF('Fixture 총 발주수량'!B:B,C45,'Fixture 총 발주수량'!AG:AG)<0,ABS(SUMIF('Fixture 총 발주수량'!B:B,C45,'Fixture 총 발주수량'!AG:AG)),0) -> 69 | J45: =SUM(M45:AQ45) -> 0 | K45: =J45-(F45+G45) -> -175 | L45: =IF(K45>=0,0.0001,ABS(K45)/400) -> 0.4375

Sheet 생산계획
K1: Y
B2: 기준월 | C2: 46143 | D2: Up-Data | E2: 46169 | F2: 0.60972222
B3: 생산계획 | S3: =C2 -> 46143 | T3: =S3+1 -> 46144 | U3: =T3+1 -> 46145 | V3: =U3+1 -> 46146 | W3: =V3+1 -> 46147 | X3: =W3+1 -> 46148 | Y3: =X3+1 -> 46149 | Z3: =Y3+1 -> 46150 | AA3: =Z3+1 -> 46151 | ... AW3: =AV3+1 -> 46173
B4: CODE | C4: Name | D4: Specificaton (CE) | E4: 생산 필요수량 | F4: 필요-계획 | G4: 계획수량 | H4: 생산수량 | I4: 진척율 | J4: 필요일수 | K4: 배정설비 | L4: 시작일 | M4: 종료일 | N4: 2호기 누적 | O4: 1호기누적 | P4: 3호기누적 | Q4: 4호기누적 | R4: 실적 | S4: =S3 -> 46143 | T4: =T3 -> 46144 | U4: =U3 -> 46145 | V4: =V3 -> 46146 | W4: =W3 -> 46147 | X4: =X3 -> 46148 | Y4: =Y3 -> 46149 | Z4: =Z3 -> 46150 | ... AW4: =AW3 -> 46173
B5: C1M3008C | C5: CORE1 Fixture | D5: Ø3.0 x 8.5mm | E5: =ABS(SUMIFS('Fixture 총 발주수량'!AH:AH,'Fixture 총 발주수량'!B:B,생산계획!B5,'Fixture 총 발주수량'!AH:AH,"<0")) -> 596 | F5: =G5-E5 -> 304 | G5: =SUMIF(S5:AW5, ">0") -> 900 | H5: =SUMIF(S6:AW6, ">0") -> 0 | I5: =IFERROR(H5/G5,) -> 0 | J5: =ROUNDUP(E5/300,) -> 2 | K5: 2호기 | L5: =N5 -> 2 | M5: =L5+J5 -> 4 | N5: =J5 -> 2 | O5: 0 | P5: 0 | Q5: 0 | R5: 계획수량 | AQ5: 300 | AR5: 300 | AS5: 300
R6: 생산수량 | S6: =INDEX('생산수량Back-Data'!$B$5:$AAA$10041, MATCH($B5,'생산수량Back-Data'!$B$5:$B$10041,0), MATCH(S$3,'생산수량Back-Data'!$B$3:$AAA$3,0)) -> 0 | T6: =INDEX('생산수량Back-Data'!$B$5:$AAA$10041, MATCH($B5,'생산수량Back-Data'!$B$5:$B$10041,0), MATCH(T$3,'생산수량Back-Data'!$B$3:$AAA$3,0)) -> 0 | U6: =INDEX('생산수량Back-Data'!$B$5:$AAA$10041, MATCH($B5,'생산수량Back-Data'!$B$5:$B$10041,0), MATCH(U$3,'생산수량Back-Data'!$B$3:$AAA$3,0)) -> 0 | V6: =INDEX('생산수량Back-Data'!$B$5:$AAA$10041, MATCH($B5,'생산수량Back-Data'!$B$5:$B$10041,0), MATCH(V$3,'생산수량Back-Data'!$B$3:$AAA$3,0)) -> 0 | W6: =INDEX('생산수량Back-Data'!$B$5:$AAA$10041, MATCH($B5,'생산수량Back-Data'!$B$5:$B$10041,0), MATCH(W$3,'생산수량Back-Data'!$B$3:$AAA$3,0)) -> 0 | X6: =INDEX('생산수량Back-Data'!$B$5:$AAA$10041, MATCH($B5,'생산수량Back-Data'!$B$5:$B$10041,0), MATCH(X$3,'생산수량Back-Data'!$B$3:$AAA$3,0)) -> 0 | Y6: =INDEX('생산수량Back-Data'!$B$5:$AAA$10041, MATCH($B5,'생산수량Back-Data'!$B$5:$B$10041,0), MATCH(Y$3,'생산수량Back-Data'!$B$3:$AAA$3,0)) -> 0 | Z6: =INDEX('생산수량Back-Data'!$B$5:$AAA$10041, MATCH($B5,'생산수량Back-Data'!$B$5:$B$10041,0), MATCH(Z$3,'생산수량Back-Data'!$B$3:$AAA$3,0)) -> 0 | ... AW6: =INDEX('생산수량Back-Data'!$B$5:$AAA$10041, MATCH($B5,'생산수량Back-Data'!$B$5:$B$10041,0), MATCH(AW$3,'생산수량Back-Data'!$B$3:$AAA$3,0)) -> 0
B7: C1M3010C | C7: CORE1 Fixture | D7: Ø3.0 x 10.0mm | E7: =ABS(SUMIFS('Fixture 총 발주수량'!AH:AH,'Fixture 총 발주수량'!B:B,생산계획!B7,'Fixture 총 발주수량'!AH:AH,"<0")) -> 253 | F7: =G7-E7 -> 2747 | G7: =SUMIF(S7:AW7, ">0") -> 3000 | H7: =SUMIF(S8:AW8, ">0") -> 2900 | I7: =IFERROR(H7/G7,) -> 0.96666667 | J7: =ROUNDUP(E7/300,) -> 1 | K7: 2호기 | L7: =L5+J7 -> 3 | M7: =L7+J7 -> 4 | N7: =N5+J7 -> 3 | O7: 0 | P7: 0 | Q7: 0 | R7: 계획수량 | AA7: 300 | AB7: 300 | AC7: 300 | AD7: 300 | AE7: 300 | AF7: 300 | AG7: 300 | AH7: 300 | AI7: 300 | AJ7: 300
R8: 생산수량 | S8: =INDEX('생산수량Back-Data'!$B$5:$AAA$10041, MATCH($B7,'생산수량Back-Data'!$B$5:$B$10041,0), MATCH(S$3,'생산수량Back-Data'!$B$3:$AAA$3,0)) -> 0 | T8: =INDEX('생산수량Back-Data'!$B$5:$AAA$10041, MATCH($B7,'생산수량Back-Data'!$B$5:$B$10041,0), MATCH(T$3,'생산수량Back-Data'!$B$3:$AAA$3,0)) -> 0 | U8: =INDEX('생산수량Back-Data'!$B$5:$AAA$10041, MATCH($B7,'생산수량Back-Data'!$B$5:$B$10041,0), MATCH(U$3,'생산수량Back-Data'!$B$3:$AAA$3,0)) -> 0 | V8: =INDEX('생산수량Back-Data'!$B$5:$AAA$10041, MATCH($B7,'생산수량Back-Data'!$B$5:$B$10041,0), MATCH(V$3,'생산수량Back-Data'!$B$3:$AAA$3,0)) -> 0 | W8: =INDEX('생산수량Back-Data'!$B$5:$AAA$10041, MATCH($B7,'생산수량Back-Data'!$B$5:$B$10041,0), MATCH(W$3,'생산수량Back-Data'!$B$3:$AAA$3,0)) -> 0 | X8: =INDEX('생산수량Back-Data'!$B$5:$AAA$10041, MATCH($B7,'생산수량Back-Data'!$B$5:$B$10041,0), MATCH(X$3,'생산수량Back-Data'!$B$3:$AAA$3,0)) -> 0 | Y8: =INDEX('생산수량Back-Data'!$B$5:$AAA$10041, MATCH($B7,'생산수량Back-Data'!$B$5:$B$10041,0), MATCH(Y$3,'생산수량Back-Data'!$B$3:$AAA$3,0)) -> 0 | Z8: =INDEX('생산수량Back-Data'!$B$5:$AAA$10041, MATCH($B7,'생산수량Back-Data'!$B$5:$B$10041,0), MATCH(Z$3,'생산수량Back-Data'!$B$3:$AAA$3,0)) -> 0 | ... AW8: =INDEX('생산수량Back-Data'!$B$5:$AAA$10041, MATCH($B7,'생산수량Back-Data'!$B$5:$B$10041,0), MATCH(AW$3,'생산수량Back-Data'!$B$3:$AAA$3,0)) -> 0
B9: C1M3011C | C9: CORE1 Fixture | D9: Ø3.0 x 11.5mm | E9: =ABS(SUMIFS('Fixture 총 발주수량'!AH:AH,'Fixture 총 발주수량'!B:B,생산계획!B9,'Fixture 총 발주수량'!AH:AH,"<0")) -> 903 | F9: =G9-E9 -> -3 | G9: =SUMIF(S9:AW9, ">0") -> 900 | H9: =SUMIF(S10:AW10, ">0") -> 900 | I9: =IFERROR(H9/G9,) -> 1 | J9: =ROUNDUP(E9/300,) -> 4 | K9: 2호기 | L9: =L7+J9 -> 7 | M9: =L9+J9 -> 11 | N9: =N7+J9 -> 7 | O9: 0 | P9: 0 | Q9: 0 | R9: 계획수량 | AN9: 300 | AO9: 300 | AP9: 300
R10: 생산수량 | S10: =INDEX('생산수량Back-Data'!$B$5:$AAA$10041, MATCH($B9,'생산수량Back-Data'!$B$5:$B$10041,0), MATCH(S$3,'생산수량Back-Data'!$B$3:$AAA$3,0)) -> 0 | T10: =INDEX('생산수량Back-Data'!$B$5:$AAA$10041, MATCH($B9,'생산수량Back-Data'!$B$5:$B$10041,0), MATCH(T$3,'생산수량Back-Data'!$B$3:$AAA$3,0)) -> 0 | U10: =INDEX('생산수량Back-Data'!$B$5:$AAA$10041, MATCH($B9,'생산수량Back-Data'!$B$5:$B$10041,0), MATCH(U$3,'생산수량Back-Data'!$B$3:$AAA$3,0)) -> 0 | V10: =INDEX('생산수량Back-Data'!$B$5:$AAA$10041, MATCH($B9,'생산수량Back-Data'!$B$5:$B$10041,0), MATCH(V$3,'생산수량Back-Data'!$B$3:$AAA$3,0)) -> 0 | W10: =INDEX('생산수량Back-Data'!$B$5:$AAA$10041, MATCH($B9,'생산수량Back-Data'!$B$5:$B$10041,0), MATCH(W$3,'생산수량Back-Data'!$B$3:$AAA$3,0)) -> 0 | X10: =INDEX('생산수량Back-Data'!$B$5:$AAA$10041, MATCH($B9,'생산수량Back-Data'!$B$5:$B$10041,0), MATCH(X$3,'생산수량Back-Data'!$B$3:$AAA$3,0)) -> 0 | Y10: =INDEX('생산수량Back-Data'!$B$5:$AAA$10041, MATCH($B9,'생산수량Back-Data'!$B$5:$B$10041,0), MATCH(Y$3,'생산수량Back-Data'!$B$3:$AAA$3,0)) -> 0 | Z10: =INDEX('생산수량Back-Data'!$B$5:$AAA$10041, MATCH($B9,'생산수량Back-Data'!$B$5:$B$10041,0), MATCH(Z$3,'생산수량Back-Data'!$B$3:$AAA$3,0)) -> 0 | ... AW10: =INDEX('생산수량Back-Data'!$B$5:$AAA$10041, MATCH($B9,'생산수량Back-Data'!$B$5:$B$10041,0), MATCH(AW$3,'생산수량Back-Data'!$B$3:$AAA$3,0)) -> 0
B11: C1M3013C | C11: CORE1 Fixture | D11: Ø3.0 x 13.0mm | E11: =ABS(SUMIFS('Fixture 총 발주수량'!AH:AH,'Fixture 총 발주수량'!B:B,생산계획!B11,'Fixture 총 발주수량'!AH:AH,"<0")) -> 485 | F11: =G11-E11 -> 415 | G11: =SUMIF(S11:AW11, ">0") -> 900 | H11: =SUMIF(S12:AW12, ">0") -> 900 | I11: =IFERROR(H11/G11,) -> 1 | J11: =ROUNDUP(E11/300,) -> 2 | K11: 2호기 | L11: =L9+J11 -> 9 | M11: =L11+J11 -> 11 | N11: =N9+J11 -> 9 | O11: 0 | P11: 0 | Q11: 0 | R11: 계획수량 | AK11: 300 | AL11: 300 | AM11: 300
R12: 생산수량 | S12: =INDEX('생산수량Back-Data'!$B$5:$AAA$10041, MATCH($B11,'생산수량Back-Data'!$B$5:$B$10041,0), MATCH(S$3,'생산수량Back-Data'!$B$3:$AAA$3,0)) -> 0 | T12: =INDEX('생산수량Back-Data'!$B$5:$AAA$10041, MATCH($B11,'생산수량Back-Data'!$B$5:$B$10041,0), MATCH(T$3,'생산수량Back-Data'!$B$3:$AAA$3,0)) -> 0 | U12: =INDEX('생산수량Back-Data'!$B$5:$AAA$10041, MATCH($B11,'생산수량Back-Data'!$B$5:$B$10041,0), MATCH(U$3,'생산수량Back-Data'!$B$3:$AAA$3,0)) -> 0 | V12: =INDEX('생산수량Back-Data'!$B$5:$AAA$10041, MATCH($B11,'생산수량Back-Data'!$B$5:$B$10041,0), MATCH(V$3,'생산수량Back-Data'!$B$3:$AAA$3,0)) -> 0 | W12: =INDEX('생산수량Back-Data'!$B$5:$AAA$10041, MATCH($B11,'생산수량Back-Data'!$B$5:$B$10041,0), MATCH(W$3,'생산수량Back-Data'!$B$3:$AAA$3,0)) -> 0 | X12: =INDEX('생산수량Back-Data'!$B$5:$AAA$10041, MATCH($B11,'생산수량Back-Data'!$B$5:$B$10041,0), MATCH(X$3,'생산수량Back-Data'!$B$3:$AAA$3,0)) -> 0 | Y12: =INDEX('생산수량Back-Data'!$B$5:$AAA$10041, MATCH($B11,'생산수량Back-Data'!$B$5:$B$10041,0), MATCH(Y$3,'생산수량Back-Data'!$B$3:$AAA$3,0)) -> 0 | Z12: =INDEX('생산수량Back-Data'!$B$5:$AAA$10041, MATCH($B11,'생산수량Back-Data'!$B$5:$B$10041,0), MATCH(Z$3,'생산수량Back-Data'!$B$3:$AAA$3,0)) -> 0 | ... AW12: =INDEX('생산수량Back-Data'!$B$5:$AAA$10041, MATCH($B11,'생산수량Back-Data'!$B$5:$B$10041,0), MATCH(AW$3,'생산수량Back-Data'!$B$3:$AAA$3,0)) -> 0
B13: C1M3508SC | C13: CORE1 Fixture | D13: Ø3.5 x 8.5mm | E13: =ABS(SUMIFS('Fixture 총 발주수량'!AH:AH,'Fixture 총 발주수량'!B:B,생산계획!B13,'Fixture 총 발주수량'!AH:AH,"<0")) -> 0 | F13: =G13-E13 -> 0 | G13: =SUMIF(S13:AW13, ">0") -> 0 | H13: =SUMIF(S14:AW14, ">0") -> 0 | I13: =IFERROR(H13/G13,) -> 0 | J13: =ROUNDUP(E13/300,) -> 0 | K13: 2호기 | L13: =L11+J13 -> 9 | M13: =L13+J13 -> 9 | N13: =N11+J13 -> 9 | O13: 0 | P13: 0 | Q13: 0 | R13: 계획수량
R14: 생산수량 | S14: =INDEX('생산수량Back-Data'!$B$5:$AAA$10041, MATCH($B13,'생산수량Back-Data'!$B$5:$B$10041,0), MATCH(S$3,'생산수량Back-Data'!$B$3:$AAA$3,0)) -> 0 | T14: =INDEX('생산수량Back-Data'!$B$5:$AAA$10041, MATCH($B13,'생산수량Back-Data'!$B$5:$B$10041,0), MATCH(T$3,'생산수량Back-Data'!$B$3:$AAA$3,0)) -> 0 | U14: =INDEX('생산수량Back-Data'!$B$5:$AAA$10041, MATCH($B13,'생산수량Back-Data'!$B$5:$B$10041,0), MATCH(U$3,'생산수량Back-Data'!$B$3:$AAA$3,0)) -> 0 | V14: =INDEX('생산수량Back-Data'!$B$5:$AAA$10041, MATCH($B13,'생산수량Back-Data'!$B$5:$B$10041,0), MATCH(V$3,'생산수량Back-Data'!$B$3:$AAA$3,0)) -> 0 | W14: =INDEX('생산수량Back-Data'!$B$5:$AAA$10041, MATCH($B13,'생산수량Back-Data'!$B$5:$B$10041,0), MATCH(W$3,'생산수량Back-Data'!$B$3:$AAA$3,0)) -> 0 | X14: =INDEX('생산수량Back-Data'!$B$5:$AAA$10041, MATCH($B13,'생산수량Back-Data'!$B$5:$B$10041,0), MATCH(X$3,'생산수량Back-Data'!$B$3:$AAA$3,0)) -> 0 | Y14: =INDEX('생산수량Back-Data'!$B$5:$AAA$10041, MATCH($B13,'생산수량Back-Data'!$B$5:$B$10041,0), MATCH(Y$3,'생산수량Back-Data'!$B$3:$AAA$3,0)) -> 0 | Z14: =INDEX('생산수량Back-Data'!$B$5:$AAA$10041, MATCH($B13,'생산수량Back-Data'!$B$5:$B$10041,0), MATCH(Z$3,'생산수량Back-Data'!$B$3:$AAA$3,0)) -> 0 | ... AW14: =INDEX('생산수량Back-Data'!$B$5:$AAA$10041, MATCH($B13,'생산수량Back-Data'!$B$5:$B$10041,0), MATCH(AW$3,'생산수량Back-Data'!$B$3:$AAA$3,0)) -> 0
B15: C1M3510SC | C15: CORE1 Fixture | D15: Ø3.5 x 10.0mm | E15: =ABS(SUMIFS('Fixture 총 발주수량'!AH:AH,'Fixture 총 발주수량'!B:B,생산계획!B15,'Fixture 총 발주수량'!AH:AH,"<0")) -> 0 | F15: =G15-E15 -> 0 | G15: =SUMIF(S15:AW15, ">0") -> 0 | H15: =SUMIF(S16:AW16, ">0") -> 0 | I15: =IFERROR(H15/G15,) -> 0 | J15: =ROUNDUP(E15/300,) -> 0 | K15: 2호기 | L15: =L13+J15 -> 9 | M15: =L15+J15 -> 9 | N15: =N13+J15 -> 9 | O15: 0 | P15: 0 | Q15: 0 | R15: 계획수량
R16: 생산수량 | S16: =INDEX('생산수량Back-Data'!$B$5:$AAA$10041, MATCH($B15,'생산수량Back-Data'!$B$5:$B$10041,0), MATCH(S$3,'생산수량Back-Data'!$B$3:$AAA$3,0)) -> 0 | T16: =INDEX('생산수량Back-Data'!$B$5:$AAA$10041, MATCH($B15,'생산수량Back-Data'!$B$5:$B$10041,0), MATCH(T$3,'생산수량Back-Data'!$B$3:$AAA$3,0)) -> 0 | U16: =INDEX('생산수량Back-Data'!$B$5:$AAA$10041, MATCH($B15,'생산수량Back-Data'!$B$5:$B$10041,0), MATCH(U$3,'생산수량Back-Data'!$B$3:$AAA$3,0)) -> 0 | V16: =INDEX('생산수량Back-Data'!$B$5:$AAA$10041, MATCH($B15,'생산수량Back-Data'!$B$5:$B$10041,0), MATCH(V$3,'생산수량Back-Data'!$B$3:$AAA$3,0)) -> 0 | W16: =INDEX('생산수량Back-Data'!$B$5:$AAA$10041, MATCH($B15,'생산수량Back-Data'!$B$5:$B$10041,0), MATCH(W$3,'생산수량Back-Data'!$B$3:$AAA$3,0)) -> 0 | X16: =INDEX('생산수량Back-Data'!$B$5:$AAA$10041, MATCH($B15,'생산수량Back-Data'!$B$5:$B$10041,0), MATCH(X$3,'생산수량Back-Data'!$B$3:$AAA$3,0)) -> 0 | Y16: =INDEX('생산수량Back-Data'!$B$5:$AAA$10041, MATCH($B15,'생산수량Back-Data'!$B$5:$B$10041,0), MATCH(Y$3,'생산수량Back-Data'!$B$3:$AAA$3,0)) -> 0 | Z16: =INDEX('생산수량Back-Data'!$B$5:$AAA$10041, MATCH($B15,'생산수량Back-Data'!$B$5:$B$10041,0), MATCH(Z$3,'생산수량Back-Data'!$B$3:$AAA$3,0)) -> 0 | ... AW16: =INDEX('생산수량Back-Data'!$B$5:$AAA$10041, MATCH($B15,'생산수량Back-Data'!$B$5:$B$10041,0), MATCH(AW$3,'생산수량Back-Data'!$B$3:$AAA$3,0)) -> 0
B17: C1M3511SC | C17: CORE1 Fixture | D17: Ø3.5 x 11.5mm | E17: =ABS(SUMIFS('Fixture 총 발주수량'!AH:AH,'Fixture 총 발주수량'!B:B,생산계획!B17,'Fixture 총 발주수량'!AH:AH,"<0")) -> 0 | F17: =G17-E17 -> 0 | G17: =SUMIF(S17:AW17, ">0") -> 0 | H17: =SUMIF(S18:AW18, ">0") -> 0 | I17: =IFERROR(H17/G17,) -> 0 | J17: =ROUNDUP(E17/300,) -> 0 | K17: 2호기 | L17: =L15+J17 -> 9 | M17: =L17+J17 -> 9 | N17: =N15+J17 -> 9 | O17: 0 | P17: 0 | Q17: 0 | R17: 계획수량
R18: 생산수량 | S18: =INDEX('생산수량Back-Data'!$B$5:$AAA$10041, MATCH($B17,'생산수량Back-Data'!$B$5:$B$10041,0), MATCH(S$3,'생산수량Back-Data'!$B$3:$AAA$3,0)) -> 0 | T18: =INDEX('생산수량Back-Data'!$B$5:$AAA$10041, MATCH($B17,'생산수량Back-Data'!$B$5:$B$10041,0), MATCH(T$3,'생산수량Back-Data'!$B$3:$AAA$3,0)) -> 0 | U18: =INDEX('생산수량Back-Data'!$B$5:$AAA$10041, MATCH($B17,'생산수량Back-Data'!$B$5:$B$10041,0), MATCH(U$3,'생산수량Back-Data'!$B$3:$AAA$3,0)) -> 0 | V18: =INDEX('생산수량Back-Data'!$B$5:$AAA$10041, MATCH($B17,'생산수량Back-Data'!$B$5:$B$10041,0), MATCH(V$3,'생산수량Back-Data'!$B$3:$AAA$3,0)) -> 0 | W18: =INDEX('생산수량Back-Data'!$B$5:$AAA$10041, MATCH($B17,'생산수량Back-Data'!$B$5:$B$10041,0), MATCH(W$3,'생산수량Back-Data'!$B$3:$AAA$3,0)) -> 0 | X18: =INDEX('생산수량Back-Data'!$B$5:$AAA$10041, MATCH($B17,'생산수량Back-Data'!$B$5:$B$10041,0), MATCH(X$3,'생산수량Back-Data'!$B$3:$AAA$3,0)) -> 0 | Y18: =INDEX('생산수량Back-Data'!$B$5:$AAA$10041, MATCH($B17,'생산수량Back-Data'!$B$5:$B$10041,0), MATCH(Y$3,'생산수량Back-Data'!$B$3:$AAA$3,0)) -> 0 | Z18: =INDEX('생산수량Back-Data'!$B$5:$AAA$10041, MATCH($B17,'생산수량Back-Data'!$B$5:$B$10041,0), MATCH(Z$3,'생산수량Back-Data'!$B$3:$AAA$3,0)) -> 0 | ... AW18: =INDEX('생산수량Back-Data'!$B$5:$AAA$10041, MATCH($B17,'생산수량Back-Data'!$B$5:$B$10041,0), MATCH(AW$3,'생산수량Back-Data'!$B$3:$AAA$3,0)) -> 0
B19: C1M3513SC | C19: CORE1 Fixture | D19: Ø3.5 x 13.0mm | E19: =ABS(SUMIFS('Fixture 총 발주수량'!AH:AH,'Fixture 총 발주수량'!B:B,생산계획!B19,'Fixture 총 발주수량'!AH:AH,"<0")) -> 0 | F19: =G19-E19 -> 0 | G19: =SUMIF(S19:AW19, ">0") -> 0 | H19: =SUMIF(S20:AW20, ">0") -> 0 | I19: =IFERROR(H19/G19,) -> 0 | J19: =ROUNDUP(E19/300,) -> 0 | K19: 2호기 | L19: =L17+J19 -> 9 | M19: =L19+J19 -> 9 | N19: =N17+J19 -> 9 | O19: 0 | P19: 0 | Q19: 0 | R19: 계획수량
R20: 생산수량 | S20: =INDEX('생산수량Back-Data'!$B$5:$AAA$10041, MATCH($B19,'생산수량Back-Data'!$B$5:$B$10041,0), MATCH(S$3,'생산수량Back-Data'!$B$3:$AAA$3,0)) -> 0 | T20: =INDEX('생산수량Back-Data'!$B$5:$AAA$10041, MATCH($B19,'생산수량Back-Data'!$B$5:$B$10041,0), MATCH(T$3,'생산수량Back-Data'!$B$3:$AAA$3,0)) -> 0 | U20: =INDEX('생산수량Back-Data'!$B$5:$AAA$10041, MATCH($B19,'생산수량Back-Data'!$B$5:$B$10041,0), MATCH(U$3,'생산수량Back-Data'!$B$3:$AAA$3,0)) -> 0 | V20: =INDEX('생산수량Back-Data'!$B$5:$AAA$10041, MATCH($B19,'생산수량Back-Data'!$B$5:$B$10041,0), MATCH(V$3,'생산수량Back-Data'!$B$3:$AAA$3,0)) -> 0 | W20: =INDEX('생산수량Back-Data'!$B$5:$AAA$10041, MATCH($B19,'생산수량Back-Data'!$B$5:$B$10041,0), MATCH(W$3,'생산수량Back-Data'!$B$3:$AAA$3,0)) -> 0 | X20: =INDEX('생산수량Back-Data'!$B$5:$AAA$10041, MATCH($B19,'생산수량Back-Data'!$B$5:$B$10041,0), MATCH(X$3,'생산수량Back-Data'!$B$3:$AAA$3,0)) -> 0 | Y20: =INDEX('생산수량Back-Data'!$B$5:$AAA$10041, MATCH($B19,'생산수량Back-Data'!$B$5:$B$10041,0), MATCH(Y$3,'생산수량Back-Data'!$B$3:$AAA$3,0)) -> 0 | Z20: =INDEX('생산수량Back-Data'!$B$5:$AAA$10041, MATCH($B19,'생산수량Back-Data'!$B$5:$B$10041,0), MATCH(Z$3,'생산수량Back-Data'!$B$3:$AAA$3,0)) -> 0 | ... AW20: =INDEX('생산수량Back-Data'!$B$5:$AAA$10041, MATCH($B19,'생산수량Back-Data'!$B$5:$B$10041,0), MATCH(AW$3,'생산수량Back-Data'!$B$3:$AAA$3,0)) -> 0
B21: C1M3508C | C21: CORE1 Fixture | D21: Ø3.5 x 8.5mm | E21: =ABS(SUMIFS('Fixture 총 발주수량'!AH:AH,'Fixture 총 발주수량'!B:B,생산계획!B21,'Fixture 총 발주수량'!AH:AH,"<0")) -> 1401 | F21: =G21-E21 -> -201 | G21: =SUMIF(S21:AW21, ">0") -> 1200 | H21: =SUMIF(S22:AW22, ">0") -> 1200 | I21: =IFERROR(H21/G21,) -> 1 | J21: =ROUNDUP(E21/300,) -> 5 | K21: 2호기 | L21: =L19+J21 -> 14 | M21: =L21+J21 -> 19 | N21: =N19+J21 -> 14 | O21: 0 | P21: 0 | Q21: 0 | R21: 계획수량 | S21: 300 | X21: 300 | Y21: 300 | Z21: 300
R22: 생산수량 | S22: =INDEX('생산수량Back-Data'!$B$5:$AAA$10041, MATCH($B21,'생산수량Back-Data'!$B$5:$B$10041,0), MATCH(S$3,'생산수량Back-Data'!$B$3:$AAA$3,0)) -> 300 | T22: =INDEX('생산수량Back-Data'!$B$5:$AAA$10041, MATCH($B21,'생산수량Back-Data'!$B$5:$B$10041,0), MATCH(T$3,'생산수량Back-Data'!$B$3:$AAA$3,0)) -> 0 | U22: =INDEX('생산수량Back-Data'!$B$5:$AAA$10041, MATCH($B21,'생산수량Back-Data'!$B$5:$B$10041,0), MATCH(U$3,'생산수량Back-Data'!$B$3:$AAA$3,0)) -> 0 | V22: =INDEX('생산수량Back-Data'!$B$5:$AAA$10041, MATCH($B21,'생산수량Back-Data'!$B$5:$B$10041,0), MATCH(V$3,'생산수량Back-Data'!$B$3:$AAA$3,0)) -> 0 | W22: =INDEX('생산수량Back-Data'!$B$5:$AAA$10041, MATCH($B21,'생산수량Back-Data'!$B$5:$B$10041,0), MATCH(W$3,'생산수량Back-Data'!$B$3:$AAA$3,0)) -> 0 | X22: =INDEX('생산수량Back-Data'!$B$5:$AAA$10041, MATCH($B21,'생산수량Back-Data'!$B$5:$B$10041,0), MATCH(X$3,'생산수량Back-Data'!$B$3:$AAA$3,0)) -> 300 | Y22: =INDEX('생산수량Back-Data'!$B$5:$AAA$10041, MATCH($B21,'생산수량Back-Data'!$B$5:$B$10041,0), MATCH(Y$3,'생산수량Back-Data'!$B$3:$AAA$3,0)) -> 300 | Z22: =INDEX('생산수량Back-Data'!$B$5:$AAA$10041, MATCH($B21,'생산수량Back-Data'!$B$5:$B$10041,0), MATCH(Z$3,'생산수량Back-Data'!$B$3:$AAA$3,0)) -> 300 | ... AW22: =INDEX('생산수량Back-Data'!$B$5:$AAA$10041, MATCH($B21,'생산수량Back-Data'!$B$5:$B$10041,0), MATCH(AW$3,'생산수량Back-Data'!$B$3:$AAA$3,0)) -> 0
B23: C1M3510C | C23: CORE1 Fixture | D23: Ø3.5 x 10.0mm | E23: =ABS(SUMIFS('Fixture 총 발주수량'!AH:AH,'Fixture 총 발주수량'!B:B,생산계획!B23,'Fixture 총 발주수량'!AH:AH,"<0")) -> 1230 | F23: =G23-E23 -> -1230 | G23: =SUMIF(S23:AW23, ">0") -> 0 | H23: =SUMIF(S24:AW24, ">0") -> 0 | I23: =IFERROR(H23/G23,) -> 0 | J23: =ROUNDUP(E23/300,) -> 5 | K23: 2호기 | L23: =L21+J23 -> 19 | M23: =L23+J23 -> 24 | N23: =N21+J23 -> 19 | O23: 0 | P23: 0 | Q23: 0 | R23: 계획수량
R24: 생산수량 | S24: =INDEX('생산수량Back-Data'!$B$5:$AAA$10041, MATCH($B23,'생산수량Back-Data'!$B$5:$B$10041,0), MATCH(S$3,'생산수량Back-Data'!$B$3:$AAA$3,0)) -> 0 | T24: =INDEX('생산수량Back-Data'!$B$5:$AAA$10041, MATCH($B23,'생산수량Back-Data'!$B$5:$B$10041,0), MATCH(T$3,'생산수량Back-Data'!$B$3:$AAA$3,0)) -> 0 | U24: =INDEX('생산수량Back-Data'!$B$5:$AAA$10041, MATCH($B23,'생산수량Back-Data'!$B$5:$B$10041,0), MATCH(U$3,'생산수량Back-Data'!$B$3:$AAA$3,0)) -> 0 | V24: =INDEX('생산수량Back-Data'!$B$5:$AAA$10041, MATCH($B23,'생산수량Back-Data'!$B$5:$B$10041,0), MATCH(V$3,'생산수량Back-Data'!$B$3:$AAA$3,0)) -> 0 | W24: =INDEX('생산수량Back-Data'!$B$5:$AAA$10041, MATCH($B23,'생산수량Back-Data'!$B$5:$B$10041,0), MATCH(W$3,'생산수량Back-Data'!$B$3:$AAA$3,0)) -> 0 | X24: =INDEX('생산수량Back-Data'!$B$5:$AAA$10041, MATCH($B23,'생산수량Back-Data'!$B$5:$B$10041,0), MATCH(X$3,'생산수량Back-Data'!$B$3:$AAA$3,0)) -> 0 | Y24: =INDEX('생산수량Back-Data'!$B$5:$AAA$10041, MATCH($B23,'생산수량Back-Data'!$B$5:$B$10041,0), MATCH(Y$3,'생산수량Back-Data'!$B$3:$AAA$3,0)) -> 0 | Z24: =INDEX('생산수량Back-Data'!$B$5:$AAA$10041, MATCH($B23,'생산수량Back-Data'!$B$5:$B$10041,0), MATCH(Z$3,'생산수량Back-Data'!$B$3:$AAA$3,0)) -> 0 | ... AW24: =INDEX('생산수량Back-Data'!$B$5:$AAA$10041, MATCH($B23,'생산수량Back-Data'!$B$5:$B$10041,0), MATCH(AW$3,'생산수량Back-Data'!$B$3:$AAA$3,0)) -> 0
B25: C1M3511C | C25: CORE1 Fixture | D25: Ø3.5 x 11.5mm | E25: =ABS(SUMIFS('Fixture 총 발주수량'!AH:AH,'Fixture 총 발주수량'!B:B,생산계획!B25,'Fixture 총 발주수량'!AH:AH,"<0")) -> 2549 | F25: =G25-E25 -> -1949 | G25: =SUMIF(S25:AW25, ">0") -> 600 | H25: =SUMIF(S26:AW26, ">0") -> 0 | I25: =IFERROR(H25/G25,) -> 0 | J25: =ROUNDUP(E25/300,) -> 9 | K25: 2호기 | L25: =L23+J25 -> 28 | M25: =L25+J25 -> 37 | N25: =N23+J25 -> 28 | O25: 0 | P25: 0 | Q25: 0 | R25: 계획수량 | AT25: 300 | AU25: 300
